Workbook

Sheet Financials>

Sheet Historical_FS
B2: ="Historical Financial Statement -"&DataSheet!B1 -> Historical Financial Statement -STYLAM INDUSTRIES LTD
B3: Years | C3: =DataSheet!B16 -> 42460 | D3: =DataSheet!C16 -> 42825 | E3: =DataSheet!D16 -> 43190 | F3: =DataSheet!E16 -> 43555 | G3: =DataSheet!F16 -> 43921 | H3: =DataSheet!G16 -> 44286 | I3: =DataSheet!H16 -> 44651 | J3: =DataSheet!I16 -> 45016 | ... L3: =DataSheet!K16 -> 45747 | M3: LTM
A5: # | B5: Income Statement
B6: Sales | C6: =IFERROR(DataSheet!B17,0) -> 264.26 | D6: =IFERROR(DataSheet!C17,0) -> 294.35 | E6: =IFERROR(DataSheet!D17,0) -> 339.08 | F6: =IFERROR(DataSheet!E17,0) -> 460.62 | G6: =IFERROR(DataSheet!F17,0) -> 462.15 | H6: =IFERROR(DataSheet!G17,0) -> 479.53 | I6: =IFERROR(DataSheet!H17,0) -> 659.35 | J6: =IFERROR(DataSheet!I17,0) -> 952.13 | ... L6: =IFERROR(DataSheet!K17,0) -> 1025.09 | M6: =SUM(DataSheet!H42:K42) -> 1095.18
B7: Sales Growth | D7: =D6/C6-1 -> 0.11386513 | E7: =E6/D6-1 -> 0.15196195 | F7: =F6/E6-1 -> 0.35844049 | G7: =G6/F6-1 -> 0.00332161 | H7: =H6/G6-1 -> 0.037606838 | I7: =I6/H6-1 -> 0.37499218 | J7: =J6/I6-1 -> 0.44404338 | K7: =K6/J6-1 -> -0.03996303 | ... M7: =M6/L6-1 -> 0.068374484
B9: COGS | C9: =IFERROR(SUM(DataSheet!B18,DataSheet!B20,DataSheet!B21,DataSheet!B22)-1*(DataSheet!B19),0) -> 192.19 | D9: =IFERROR(SUM(DataSheet!C18,DataSheet!C20,DataSheet!C21,DataSheet!C22)-1*(DataSheet!C19),0) -> 208.96 | E9: =IFERROR(SUM(DataSheet!D18,DataSheet!D20,DataSheet!D21,DataSheet!D22)-1*(DataSheet!D19),0) -> 255.94 | F9: =IFERROR(SUM(DataSheet!E18,DataSheet!E20,DataSheet!E21,DataSheet!E22)-1*(DataSheet!E19),0) -> 342.63 | G9: =IFERROR(SUM(DataSheet!F18,DataSheet!F20,DataSheet!F21,DataSheet!F22)-1*(DataSheet!F19),0) -> 343.71 | H9: =IFERROR(SUM(DataSheet!G18,DataSheet!G20,DataSheet!G21,DataSheet!G22)-1*(DataSheet!G19),0) -> 336.59 | I9: =IFERROR(SUM(DataSheet!H18,DataSheet!H20,DataSheet!H21,DataSheet!H22)-1*(DataSheet!H19),0) -> 494.65 | J9: =IFERROR(SUM(DataSheet!I18,DataSheet!I20,DataSheet!I21,DataSheet!I22)-1*(DataSheet!I19),0) -> 691.41 | ... L9: =IFERROR(SUM(DataSheet!K18,DataSheet!K20,DataSheet!K21,DataSheet!K22)-1*(DataSheet!K19),0) -> 735.35 | M9: =IFERROR(SUM(DataSheet!H43:K43),0) -> 896.73
B10: COGS % Sales | C10: =C9/C6 -> 0.72727617 | D10: =D9/D6 -> 0.70990318 | E10: =E9/E6 -> 0.75480713 | F10: =F9/F6 -> 0.74384525 | G10: =G9/G6 -> 0.74371957 | H10: =H9/H6 -> 0.70191646 | I10: =I9/I6 -> 0.75020854 | J10: =J9/J6 -> 0.72617185 | ... M10: =M9/M6 -> 0.81879691
B12: Gross Profit | C12: =C6-C9 -> 72.07 | D12: =D6-D9 -> 85.39 | E12: =E6-E9 -> 83.14 | F12: =F6-F9 -> 117.99 | G12: =G6-G9 -> 118.44 | H12: =H6-H9 -> 142.94 | I12: =I6-I9 -> 164.7 | J12: =J6-J9 -> 260.72 | ... M12: =M6-M9 -> 198.45
B13: Gross Margin | C13: =C12/C6 -> 0.27272383 | D13: =D12/D6 -> 0.29009682 | E13: =E12/E6 -> 0.24519287 | F13: =F12/F6 -> 0.25615475 | G13: =G12/G6 -> 0.25628043 | H13: =H12/H6 -> 0.29808354 | I13: =I12/I6 -> 0.24979146 | J13: =J12/J6 -> 0.27382815 | ... M13: =M12/M6 -> 0.18120309
B15: Selling and General Expenses | C15: =IFERROR(DataSheet!B23+DataSheet!B24,0) -> 41.88 | D15: =IFERROR(DataSheet!C23+DataSheet!C24,0) -> 39.56 | E15: =IFERROR(DataSheet!D23+DataSheet!D24,0) -> 33.61 | F15: =IFERROR(DataSheet!E23+DataSheet!E24,0) -> 37.82 | G15: =IFERROR(DataSheet!F23+DataSheet!F24,0) -> 38.72 | H15: =IFERROR(DataSheet!G23+DataSheet!G24,0) -> 43.83 | I15: =IFERROR(DataSheet!H23+DataSheet!H24,0) -> 61.06 | J15: =IFERROR(DataSheet!I23+DataSheet!I24,0) -> 105.91 | ... L15: =IFERROR(DataSheet!K23+DataSheet!K24,0) -> 104.29
B16: S&G Exp % Sales | C16: =C15/C6 -> 0.15848028 | D16: =D15/D6 -> 0.13439783 | E16: =E15/E6 -> 0.099121151 | F16: =F15/F6 -> 0.082106726 | G16: =G15/G6 -> 0.083782322 | H16: =H15/H6 -> 0.091401998 | I16: =I15/I6 -> 0.092606355 | J16: =J15/J6 -> 0.11123481 | ... L16: =L15/L6 -> 0.10173741
B18: EBITDA | C18: =C12-C15 -> 30.19 | D18: =D12-D15 -> 45.83 | E18: =E12-E15 -> 49.53 | F18: =F12-F15 -> 80.17 | G18: =G12-G15 -> 79.72 | H18: =H12-H15 -> 99.11 | I18: =I12-I15 -> 103.64 | J18: =J12-J15 -> 154.81 | ... L18: =L12-L15 -> 185.45 | M18: =IFERROR(SUM(DataSheet!H50:K50),0) -> 198.45
B19: EBITDA Margin | C19: =C18/C6 -> 0.11424355 | D19: =D18/D6 -> 0.155699 | E19: =E18/E6 -> 0.14607172 | F19: =F18/F6 -> 0.17404802 | G19: =G18/G6 -> 0.17249811 | H19: =H18/H6 -> 0.20668154 | I19: =I18/I6 -> 0.15718511 | J19: =J18/J6 -> 0.16259334 | ... M19: =M18/M6 -> 0.18120309
B21: Depreciation | C21: =IFERROR(DataSheet!B26,0) -> 4.65 | D21: =IFERROR(DataSheet!C26,0) -> 5.7 | E21: =IFERROR(DataSheet!D26,0) -> 10.83 | F21: =IFERROR(DataSheet!E26,0) -> 18.21 | G21: =IFERROR(DataSheet!F26,0) -> 20.98 | H21: =IFERROR(DataSheet!G26,0) -> 23.15 | I21: =IFERROR(DataSheet!H26,0) -> 23.26 | J21: =IFERROR(DataSheet!I26,0) -> 19.99 | ... L21: =IFERROR(DataSheet!K26,0) -> 23.87 | M21: =IFERROR(SUM(DataSheet!H45:K45),0) -> 22.09
B22: Depreciation % Sales | C22: =C21/C6 -> 0.017596307 | D22: =D21/D6 -> 0.019364702 | E22: =E21/E6 -> 0.031939365 | F22: =F21/F6 -> 0.039533672 | G22: =G21/G6 -> 0.045396516 | H22: =H21/H6 -> 0.048276437 | I22: =I21/I6 -> 0.035277167 | J22: =J21/J6 -> 0.020995032 | ... M22: =M21/M6 -> 0.0201702
B24: EBIT | C24: =C18-C21 -> 25.54 | D24: =D18-D21 -> 40.13 | E24: =E18-E21 -> 38.7 | F24: =F18-F21 -> 61.96 | G24: =G18-G21 -> 58.74 | H24: =H18-H21 -> 75.96 | I24: =I18-I21 -> 80.38 | J24: =J18-J21 -> 134.82 | ... M24: =M18-M21 -> 176.36
B25: EBIT % Sales | C25: =C24/C6 -> 0.096647241 | D25: =D24/D6 -> 0.1363343 | E25: =E24/E6 -> 0.11413236 | F25: =F24/F6 -> 0.13451435 | G25: =G24/G6 -> 0.12710159 | H25: =H24/H6 -> 0.1584051 | I25: =I24/I6 -> 0.12190794 | J25: =J24/J6 -> 0.14159831 | ... M25: =M24/M6 -> 0.16103289
B27: Interest | C27: =IFERROR(DataSheet!B27,0) -> 6.46 | D27: =IFERROR(DataSheet!C27,0) -> 10.02 | E27: =IFERROR(DataSheet!D27,0) -> 7.7 | F27: =IFERROR(DataSheet!E27,0) -> 11.41 | G27: =IFERROR(DataSheet!F27,0) -> 10.9 | H27: =IFERROR(DataSheet!G27,0) -> 6.02 | I27: =IFERROR(DataSheet!H27,0) -> 7.83 | J27: =IFERROR(DataSheet!I27,0) -> 8.19 | ... L27: =IFERROR(DataSheet!K27,0) -> 4.18 | M27: =IFERROR(SUM(DataSheet!H46:K46),0) -> 8.73
B28: Interest % Sales | C28: =C27/C6 -> 0.024445622 | D28: =D27/D6 -> 0.034041108 | E28: =E27/E6 -> 0.022708505 | F28: =F27/F6 -> 0.024770961 | G28: =G27/G6 -> 0.023585416 | H28: =H27/H6 -> 0.012553959 | I28: =I27/I6 -> 0.011875332 | J28: =J27/J6 -> 0.0086017666 | ... M28: =M27/M6 -> 0.0079712924
B30: Other Income | C30: =IFERROR(DataSheet!B25,0) -> 0.6 | D30: =IFERROR(DataSheet!C25,0) -> 1.06 | E30: =IFERROR(DataSheet!D25,0) -> 2.06 | F30: =IFERROR(DataSheet!E25,0) -> 1.34 | G30: =IFERROR(DataSheet!F25,0) -> -14.33 | H30: =IFERROR(DataSheet!G25,0) -> 1.03 | I30: =IFERROR(DataSheet!H25,0) -> 7.92 | J30: =IFERROR(DataSheet!I25,0) -> 1.4 | ... L30: =IFERROR(DataSheet!K25,0) -> 7.44 | M30: =IFERROR(SUM(DataSheet!H44:K44),0) -> 4.6
B31: Other Income % Sales | C31: =C30/C6 -> 0.0022704912 | D31: =D30/D6 -> 0.0036011551 | E31: =E30/E6 -> 0.0060752625 | F31: =F30/F6 -> 0.0029091225 | G31: =G30/G6 -> -0.031007249 | H31: =H30/H6 -> 0.0021479365 | I31: =I30/I6 -> 0.01201183 | J31: =J30/J6 -> 0.0014703874 | ... M31: =M30/M6 -> 0.0042002228
B33: Earning Before Tax | C33: =C18+C30-(C21+C27) -> 19.68 | D33: =D18+D30-(D21+D27) -> 31.17 | E33: =E18+E30-(E21+E27) -> 33.06 | F33: =F18+F30-(F21+F27) -> 51.89 | G33: =G18+G30-(G21+G27) -> 33.51 | H33: =H18+H30-(H21+H27) -> 70.97 | I33: =I18+I30-(I21+I27) -> 80.47 | J33: =J18+J30-(J21+J27) -> 128.03 | ... M33: =M18+M30-(M21+M27) -> 172.23
B34: EBT % Sales | C34: =C33/C6 -> 0.074472111 | D34: =D33/D6 -> 0.10589434 | E34: =E33/E6 -> 0.097499115 | F34: =F33/F6 -> 0.11265251 | G34: =G33/G6 -> 0.072508926 | H34: =H33/H6 -> 0.14799908 | I34: =I33/I6 -> 0.12204444 | J34: =J33/J6 -> 0.13446693 | ... M34: =M33/M6 -> 0.15726182
B36: Tax | C36: =IFERROR(DataSheet!B29,0) -> 7.53 | D36: =IFERROR(DataSheet!C29,0) -> 11.53 | E36: =IFERROR(DataSheet!D29,0) -> 13.01 | F36: =IFERROR(DataSheet!E29,0) -> 13.07 | G36: =IFERROR(DataSheet!F29,0) -> 14.6 | H36: =IFERROR(DataSheet!G29,0) -> 15.67 | I36: =IFERROR(DataSheet!H29,0) -> 19.46 | J36: =IFERROR(DataSheet!I29,0) -> 32.08 | ... L36: =IFERROR(DataSheet!K29,0) -> 43.01 | M36: =IFERROR(SUM(DataSheet!H48:K48),0) -> 47.25
B37: Effective Tax Rate | C37: =C36/C33 -> 0.38262195 | D37: =D36/D33 -> 0.36990696 | E37: =E36/E33 -> 0.39352692 | F37: =F36/F33 -> 0.25187897 | G37: =G36/G33 -> 0.43569084 | H37: =H36/H33 -> 0.22079752 | I37: =I36/I33 -> 0.24182925 | J37: =J36/J33 -> 0.25056627 | ... M37: =M36/M33 -> 0.27434245
B39: Net Income | C39: =C33-C36 -> 12.15 | D39: =D33-D36 -> 19.64 | E39: =E33-E36 -> 20.05 | F39: =F33-F36 -> 38.82 | G39: =G33-G36 -> 18.91 | H39: =H33-H36 -> 55.3 | I39: =I33-I36 -> 61.01 | J39: =J33-J36 -> 95.95 | ... M39: =M33-M36 -> 124.98
B40: Net Profit Margin | C40: =C39/C6 -> 0.045977446 | D40: =D39/D6 -> 0.066723289 | E40: =E39/E6 -> 0.059130589 | F40: =F39/F6 -> 0.084277713 | G40: =G39/G6 -> 0.040917451 | H40: =H39/H6 -> 0.11532125 | I40: =I39/I6 -> 0.092530522 | J40: =J39/J6 -> 0.10077405 | ... M40: =M39/M6 -> 0.11411823
B42: No of Shares | C42: =IFERROR(DataSheet!B93,0) -> 1.46 | D42: =IFERROR(DataSheet!C93,0) -> 1.46 | E42: =IFERROR(DataSheet!D93,0) -> 1.63 | F42: =IFERROR(DataSheet!E93,0) -> 1.63 | G42: =IFERROR(DataSheet!F93,0) -> 1.69 | H42: =IFERROR(DataSheet!G93,0) -> 1.69 | I42: =IFERROR(DataSheet!H93,0) -> 1.69 | J42: =IFERROR(DataSheet!I93,0) -> 1.69 | ... L42: =IFERROR(DataSheet!K93,0) -> 1.69 | M42: =L42 -> 1.69
B44: EPS | C44: =C39/C42 -> 8.3219178 | D44: =D39/D42 -> 13.452055 | E44: =E39/E42 -> 12.300613 | F44: =F39/F42 -> 23.815951 | G44: =G39/G42 -> 11.189349 | H44: =H39/H42 -> 32.721893 | I44: =I39/I42 -> 36.100592 | J44: =J39/J42 -> 56.775148 | ... M44: =M39/M42 -> 73.952663
B45: EPS Growth % | D45: =D44/C44-1 -> 0.61646091 | E45: =E44/D44-1 -> -0.085595942 | F45: =F44/E44-1 -> 0.9361596 | G45: =G44/F44-1 -> -0.53017416 | H45: =H44/G44-1 -> 1.9243786 | I45: =I44/H44-1 -> 0.10325497 | J45: =J44/I44-1 -> 0.572693 | K45: =K44/J44-1 -> 0.33819698 | ... M45: =M44/L44-1 -> 0.025855701
B47: Dividend Per Share | C47: =IFERROR(IF(DataSheet!B31/DataSheet!B93>0,DataSheet!B31/DataSheet!B93,0),0) -> 0 | D47: =IFERROR(IF(DataSheet!C31/DataSheet!C93>0,DataSheet!C31/DataSheet!C93,0),0) -> 0 | E47: =IFERROR(IF(DataSheet!D31/DataSheet!D93>0,DataSheet!D31/DataSheet!D93,0),0) -> 0 | F47: =IFERROR(IF(DataSheet!E31/DataSheet!E93>0,DataSheet!E31/DataSheet!E93,0),0) -> 0 | G47: =IFERROR(IF(DataSheet!F31/DataSheet!F93>0,DataSheet!F31/DataSheet!F93,0),0) -> 0 | H47: =IFERROR(IF(DataSheet!G31/DataSheet!G93>0,DataSheet!G31/DataSheet!G93,0),0) -> 0 | I47: =IFERROR(IF(DataSheet!H31/DataSheet!H93>0,DataSheet!H31/DataSheet!H93,0),0) -> 2.5088757 | J47: =IFERROR(IF(DataSheet!I31/DataSheet!I93>0,DataSheet!I31/DataSheet!I93,0),0) -> 0 | ... M47: =IFERROR(IF(DataSheet!L31/DataSheet!L93>0,DataSheet!L31/DataSheet!L93,0),0) -> 0
B48: Dividend Payout Ratio | C48: =IFERROR(C47/C44,0) -> 0 | D48: =IFERROR(D47/D44,0) -> 0 | E48: =IFERROR(E47/E44,0) -> 0 | F48: =IFERROR(F47/F44,0) -> 0 | G48: =IFERROR(G47/G44,0) -> 0 | H48: =IFERROR(H47/H44,0) -> 0 | I48: =IFERROR(I47/I44,0) -> 0.069496804 | J48: =IFERROR(J47/J44,0) -> 0 | ... M48: =IFERROR(M47/M44,0) -> 0
B50: Retained Earnings | C50: =IFERROR(IF(C44>C47,1-C48,0),0) -> 1 | D50: =IFERROR(IF(D44>D47,1-D48,0),0) -> 1 | E50: =IFERROR(IF(E44>E47,1-E48,0),0) -> 1 | F50: =IFERROR(IF(F44>F47,1-F48,0),0) -> 1 | G50: =IFERROR(IF(G44>G47,1-G48,0),0) -> 1 | H50: =IFERROR(IF(H44>H47,1-H48,0),0) -> 1 | I50: =IFERROR(IF(I44>I47,1-I48,0),0) -> 0.9305032 | J50: =IFERROR(IF(J44>J47,1-J48,0),0) -> 1 | ... M50: =IFERROR(IF(M44>M47,1-M48,0),0) -> 1
A52: # | B52: Balance Sheet Statement
B53: Equity Share Capital | C53: =DataSheet!B57 -> 7.32 | D53: =DataSheet!C57 -> 7.32 | E53: =DataSheet!D57 -> 8.17 | F53: =DataSheet!E57 -> 8.17 | G53: =DataSheet!F57 -> 8.47 | H53: =DataSheet!G57 -> 8.47 | I53: =DataSheet!H57 -> 8.47 | J53: =DataSheet!I57 -> 8.47 | ... L53: =DataSheet!K57 -> 8.47
B54: Reserves | C54: =DataSheet!B58 -> 48.88 | D54: =DataSheet!C58 -> 69.21 | E54: =DataSheet!D58 -> 137.47 | F54: =DataSheet!E58 -> 177.35 | G54: =DataSheet!F58 -> 195.79 | H54: =DataSheet!G58 -> 251.21 | I54: =DataSheet!H58 -> 307.97 | J54: =DataSheet!I58 -> 403.92 | ... L54: =DataSheet!K58 -> 649.15
B55: Borrowings | C55: =DataSheet!B59 -> 116.78 | D55: =DataSheet!C59 -> 184 | E55: =DataSheet!D59 -> 126.8 | F55: =DataSheet!E59 -> 189.05 | G55: =DataSheet!F59 -> 118.48 | H55: =DataSheet!G59 -> 59.15 | I55: =DataSheet!H59 -> 79.42 | J55: =DataSheet!I59 -> 46.93 | ... L55: =DataSheet!K59 -> 36.07
B56: Other Liabilities | C56: =DataSheet!B60 -> 38.12 | D56: =DataSheet!C60 -> 42.63 | E56: =DataSheet!D60 -> 55.76 | F56: =DataSheet!E60 -> 63.58 | G56: =DataSheet!F60 -> 72.56 | H56: =DataSheet!G60 -> 88.55 | I56: =DataSheet!H60 -> 93.41 | J56: =DataSheet!I60 -> 79.09 | ... L56: =DataSheet!K60 -> 84.83
B57: Total Liabilities | C57: =SUM(C53:C56) -> 211.1 | D57: =SUM(D53:D56) -> 303.16 | E57: =SUM(E53:E56) -> 328.2 | F57: =SUM(F53:F56) -> 438.15 | G57: =SUM(G53:G56) -> 395.3 | H57: =SUM(H53:H56) -> 407.38 | I57: =SUM(I53:I56) -> 489.27 | J57: =SUM(J53:J56) -> 538.41 | ... L57: =SUM(L53:L56) -> 778.52
B59: Fixed Asset Net Block | C59: =DataSheet!B62 -> 56.29 | D59: =DataSheet!C62 -> 79.68 | E59: =DataSheet!D62 -> 185.67 | F59: =DataSheet!E62 -> 233.47 | G59: =DataSheet!F62 -> 194.95 | H59: =DataSheet!G62 -> 187.82 | I59: =DataSheet!H62 -> 178.72 | J59: =DataSheet!I62 -> 171.79 | ... L59: =DataSheet!K62 -> 177.23
...

Sheet Ratio Analysis
B2: ="RATIO ANALYSIS -"&DataSheet!B1 -> RATIO ANALYSIS -STYLAM INDUSTRIES LTD
B3: Years | C3: =DataSheet!B16 -> 42460 | D3: =DataSheet!C16 -> 42825 | E3: =DataSheet!D16 -> 43190 | F3: =DataSheet!E16 -> 43555 | G3: =DataSheet!F16 -> 43921 | H3: =DataSheet!G16 -> 44286 | I3: =DataSheet!H16 -> 44651 | J3: =DataSheet!I16 -> 45016 | ... L3: =DataSheet!K16 -> 45747 | M3: Trend | N3: Mean | O3: Median
B5: Sales Growth | D5: =IFERROR(Historical_FS!D7,0) -> 0.11386513 | E5: =IFERROR(Historical_FS!E7,0) -> 0.15196195 | F5: =IFERROR(Historical_FS!F7,0) -> 0.35844049 | G5: =IFERROR(Historical_FS!G7,0) -> 0.00332161 | H5: =IFERROR(Historical_FS!H7,0) -> 0.037606838 | I5: =IFERROR(Historical_FS!I7,0) -> 0.37499218 | J5: =IFERROR(Historical_FS!J7,0) -> 0.44404338 | K5: =IFERROR(Historical_FS!K7,0) -> -0.03996303 | L5: =IFERROR(Historical_FS!L7,0) -> 0.12144451 | N5: =IFERROR(AVERAGE(D5:L5),0) -> 0.17396812 | O5: =IFERROR(MEDIAN(D5:L5),0) -> 0.12144451
B6: EBITDA Growth | D6: =IFERROR(Historical_FS!D18/Historical_FS!C18-1,0) -> 0.51805234 | E6: =IFERROR(Historical_FS!E18/Historical_FS!D18-1,0) -> 0.080733144 | F6: =IFERROR(Historical_FS!F18/Historical_FS!E18-1,0) -> 0.61861498 | G6: =IFERROR(Historical_FS!G18/Historical_FS!F18-1,0) -> -0.0056130722 | H6: =IFERROR(Historical_FS!H18/Historical_FS!G18-1,0) -> 0.24322629 | I6: =IFERROR(Historical_FS!I18/Historical_FS!H18-1,0) -> 0.04570679 | J6: =IFERROR(Historical_FS!J18/Historical_FS!I18-1,0) -> 0.49372829 | K6: =IFERROR(Historical_FS!K18/Historical_FS!J18-1,0) -> 0.18965183 | L6: =IFERROR(Historical_FS!L18/Historical_FS!K18-1,0) -> 0.0069501005 | N6: =IFERROR(AVERAGE(D6:L6),0) -> 0.24345008 | O6: =IFERROR(MEDIAN(D6:L6),0) -> 0.18965183
B7: EBIT Growth | D7: =IFERROR(Historical_FS!D24/Historical_FS!C24-1,0) -> 0.57126077 | E7: =IFERROR(Historical_FS!E24/Historical_FS!D24-1,0) -> -0.035634189 | F7: =IFERROR(Historical_FS!F24/Historical_FS!E24-1,0) -> 0.60103359 | G7: =IFERROR(Historical_FS!G24/Historical_FS!F24-1,0) -> -0.051969012 | H7: =IFERROR(Historical_FS!H24/Historical_FS!G24-1,0) -> 0.29315628 | I7: =IFERROR(Historical_FS!I24/Historical_FS!H24-1,0) -> 0.05818852 | J7: =IFERROR(Historical_FS!J24/Historical_FS!I24-1,0) -> 0.67728291 | K7: =IFERROR(Historical_FS!K24/Historical_FS!J24-1,0) -> 0.20093458 | L7: =IFERROR(Historical_FS!L24/Historical_FS!K24-1,0) -> -0.0020381694 | N7: =IFERROR(AVERAGE(D7:L7),0) -> 0.25691281 | O7: =IFERROR(MEDIAN(D7:L7),0) -> 0.20093458
B8: EBT Growth | D8: =IFERROR(Historical_FS!D33/Historical_FS!C33-1,0) -> 0.58384146 | E8: =IFERROR(Historical_FS!E33/Historical_FS!D33-1,0) -> 0.060635226 | F8: =IFERROR(Historical_FS!F33/Historical_FS!E33-1,0) -> 0.56957048 | G8: =IFERROR(Historical_FS!G33/Historical_FS!F33-1,0) -> -0.35421083 | H8: =IFERROR(Historical_FS!H33/Historical_FS!G33-1,0) -> 1.1178753 | I8: =IFERROR(Historical_FS!I33/Historical_FS!H33-1,0) -> 0.13385938 | J8: =IFERROR(Historical_FS!J33/Historical_FS!I33-1,0) -> 0.59102771 | K8: =IFERROR(Historical_FS!K33/Historical_FS!J33-1,0) -> 0.28305866 | L8: =IFERROR(Historical_FS!L33/Historical_FS!K33-1,0) -> 0.0034698971 | N8: =IFERROR(AVERAGE(D8:L8),0) -> 0.33212525 | O8: =IFERROR(MEDIAN(D8:L8),0) -> 0.28305866
B9: Net Profit Growth | D9: =IFERROR(Historical_FS!D39/Historical_FS!C39-1,0) -> 0.61646091 | E9: =IFERROR(Historical_FS!E39/Historical_FS!D39-1,0) -> 0.020875764 | F9: =IFERROR(Historical_FS!F39/Historical_FS!E39-1,0) -> 0.9361596 | G9: =IFERROR(Historical_FS!G39/Historical_FS!F39-1,0) -> -0.51287996 | H9: =IFERROR(Historical_FS!H39/Historical_FS!G39-1,0) -> 1.9243786 | I9: =IFERROR(Historical_FS!I39/Historical_FS!H39-1,0) -> 0.10325497 | J9: =IFERROR(Historical_FS!J39/Historical_FS!I39-1,0) -> 0.572693 | K9: =IFERROR(Historical_FS!K39/Historical_FS!J39-1,0) -> 0.33819698 | L9: =IFERROR(Historical_FS!L39/Historical_FS!K39-1,0) -> -0.051168224 | N9: =IFERROR(AVERAGE(D9:L9),0) -> 0.43866352 | O9: =IFERROR(MEDIAN(D9:L9),0) -> 0.33819698
B10: Dividend Growth | D10: =IFERROR(Historical_FS!D47/Historical_FS!C47-1,0) -> 0 | E10: =IFERROR(Historical_FS!E47/Historical_FS!D47-1,0) -> 0 | F10: =IFERROR(Historical_FS!F47/Historical_FS!E47-1,0) -> 0 | G10: =IFERROR(Historical_FS!G47/Historical_FS!F47-1,0) -> 0 | H10: =IFERROR(Historical_FS!H47/Historical_FS!G47-1,0) -> 0 | I10: =IFERROR(Historical_FS!I47/Historical_FS!H47-1,0) -> 0 | J10: =IFERROR(Historical_FS!J47/Historical_FS!I47-1,0) -> -1 | K10: =IFERROR(Historical_FS!K47/Historical_FS!J47-1,0) -> 0 | L10: =IFERROR(Historical_FS!L47/Historical_FS!K47-1,0) -> -1 | N10: =IFERROR(AVERAGE(D10:L10),0) -> -0.22222222 | O10: =IFERROR(MEDIAN(D10:L10),0) -> 0
B12: Gross Margin | D12: =IFERROR(Historical_FS!D10,0) -> 0.70990318 | E12: =IFERROR(Historical_FS!E10,0) -> 0.75480713 | F12: =IFERROR(Historical_FS!F10,0) -> 0.74384525 | G12: =IFERROR(Historical_FS!G10,0) -> 0.74371957 | H12: =IFERROR(Historical_FS!H10,0) -> 0.70191646 | I12: =IFERROR(Historical_FS!I10,0) -> 0.75020854 | J12: =IFERROR(Historical_FS!J10,0) -> 0.72617185 | K12: =IFERROR(Historical_FS!K10,0) -> 0.69689743 | L12: =IFERROR(Historical_FS!L10,0) -> 0.71735165 | N12: =IFERROR(AVERAGE(D12:L12),0) -> 0.72720234 | O12: =IFERROR(MEDIAN(D12:L12),0) -> 0.72617185
B13: EBITDA Margin | D13: =IFERROR(Historical_FS!D19,0) -> 0.155699 | E13: =IFERROR(Historical_FS!E19,0) -> 0.14607172 | F13: =IFERROR(Historical_FS!F19,0) -> 0.17404802 | G13: =IFERROR(Historical_FS!G19,0) -> 0.17249811 | H13: =IFERROR(Historical_FS!H19,0) -> 0.20668154 | I13: =IFERROR(Historical_FS!I19,0) -> 0.15718511 | J13: =IFERROR(Historical_FS!J19,0) -> 0.16259334 | K13: =IFERROR(Historical_FS!K19,0) -> 0.20148127 | L13: =IFERROR(Historical_FS!L19,0) -> 0.18091094 | N13: =IFERROR(AVERAGE(D13:L13),0) -> 0.17301878 | O13: =IFERROR(MEDIAN(D13:L13),0) -> 0.17249811
B14: EBIT Margin | D14: =IFERROR(Historical_FS!D25,0) -> 0.1363343 | E14: =IFERROR(Historical_FS!E25,0) -> 0.11413236 | F14: =IFERROR(Historical_FS!F25,0) -> 0.13451435 | G14: =IFERROR(Historical_FS!G25,0) -> 0.12710159 | H14: =IFERROR(Historical_FS!H25,0) -> 0.1584051 | I14: =IFERROR(Historical_FS!I25,0) -> 0.12190794 | J14: =IFERROR(Historical_FS!J25,0) -> 0.14159831 | K14: =IFERROR(Historical_FS!K25,0) -> 0.17712892 | L14: =IFERROR(Historical_FS!L25,0) -> 0.15762518 | N14: =IFERROR(AVERAGE(D14:L14),0) -> 0.14097201 | O14: =IFERROR(MEDIAN(D14:L14),0) -> 0.1363343
B15: EBT Margin | D15: =IFERROR(Historical_FS!D34,0) -> 0.10589434 | E15: =IFERROR(Historical_FS!E34,0) -> 0.097499115 | F15: =IFERROR(Historical_FS!F34,0) -> 0.11265251 | G15: =IFERROR(Historical_FS!G34,0) -> 0.072508926 | H15: =IFERROR(Historical_FS!H34,0) -> 0.14799908 | I15: =IFERROR(Historical_FS!I34,0) -> 0.12204444 | J15: =IFERROR(Historical_FS!J34,0) -> 0.13446693 | K15: =IFERROR(Historical_FS!K34,0) -> 0.17971075 | L15: =IFERROR(Historical_FS!L34,0) -> 0.16080539 | N15: =IFERROR(AVERAGE(D15:L15),0) -> 0.1259535 | O15: =IFERROR(MEDIAN(D15:L15),0) -> 0.12204444
B16: Net Profit Margin | D16: =IFERROR(Historical_FS!D40,0) -> 0.066723289 | E16: =IFERROR(Historical_FS!E40,0) -> 0.059130589 | F16: =IFERROR(Historical_FS!F40,0) -> 0.084277713 | G16: =IFERROR(Historical_FS!G40,0) -> 0.040917451 | H16: =IFERROR(Historical_FS!H40,0) -> 0.11532125 | I16: =IFERROR(Historical_FS!I40,0) -> 0.092530522 | J16: =IFERROR(Historical_FS!J40,0) -> 0.10077405 | K16: =IFERROR(Historical_FS!K40,0) -> 0.14046911 | L16: =IFERROR(Historical_FS!L40,0) -> 0.1188481 | N16: =IFERROR(AVERAGE(D16:L16),0) -> 0.09099912 | O16: =IFERROR(MEDIAN(D16:L16),0) -> 0.092530522
B18: Sales Expense%Sales | D18: =IFERROR(Historical_FS!D16,0) -> 0.13439783 | E18: =IFERROR(Historical_FS!E16,0) -> 0.099121151 | F18: =IFERROR(Historical_FS!F16,0) -> 0.082106726 | G18: =IFERROR(Historical_FS!G16,0) -> 0.083782322 | H18: =IFERROR(Historical_FS!H16,0) -> 0.091401998 | I18: =IFERROR(Historical_FS!I16,0) -> 0.092606355 | J18: =IFERROR(Historical_FS!J16,0) -> 0.11123481 | K18: =IFERROR(Historical_FS!K16,0) -> 0.1016213 | L18: =IFERROR(Historical_FS!L16,0) -> 0.10173741 | N18: =IFERROR(AVERAGE(D18:L18),0) -> 0.099778878 | O18: =IFERROR(MEDIAN(D18:L18),0) -> 0.099121151
B19: Depreciation%Sales | D19: =IFERROR(Historical_FS!D22,0) -> 0.019364702 | E19: =IFERROR(Historical_FS!E22,0) -> 0.031939365 | F19: =IFERROR(Historical_FS!F22,0) -> 0.039533672 | G19: =IFERROR(Historical_FS!G22,0) -> 0.045396516 | H19: =IFERROR(Historical_FS!H22,0) -> 0.048276437 | I19: =IFERROR(Historical_FS!I22,0) -> 0.035277167 | J19: =IFERROR(Historical_FS!J22,0) -> 0.020995032 | K19: =IFERROR(Historical_FS!K22,0) -> 0.024352354 | L19: =IFERROR(Historical_FS!L22,0) -> 0.02328576 | N19: =IFERROR(AVERAGE(D19:L19),0) -> 0.032046779 | O19: =IFERROR(MEDIAN(D19:L19),0) -> 0.031939365
B20: Operaing Income%Sales | D20: =IFERROR(Historical_FS!D40,0) -> 0.066723289 | E20: =IFERROR(Historical_FS!E40,0) -> 0.059130589 | F20: =IFERROR(Historical_FS!F40,0) -> 0.084277713 | G20: =IFERROR(Historical_FS!G40,0) -> 0.040917451 | H20: =IFERROR(Historical_FS!H40,0) -> 0.11532125 | I20: =IFERROR(Historical_FS!I40,0) -> 0.092530522 | J20: =IFERROR(Historical_FS!J40,0) -> 0.10077405 | K20: =IFERROR(Historical_FS!K40,0) -> 0.14046911 | L20: =IFERROR(Historical_FS!L40,0) -> 0.1188481 | N20: =IFERROR(AVERAGE(D20:L20),0) -> 0.09099912 | O20: =IFERROR(MEDIAN(D20:L20),0) -> 0.092530522
B22: ROCE | D22: =IFERROR(Historical_FS!D24/SUM(Historical_FS!D53:D55),0) -> 0.15403217 | E22: =IFERROR(Historical_FS!E24/SUM(Historical_FS!E53:E55),0) -> 0.14204963 | F22: =IFERROR(Historical_FS!F24/SUM(Historical_FS!F53:F55),0) -> 0.16541634 | G22: =IFERROR(Historical_FS!G24/SUM(Historical_FS!G53:G55),0) -> 0.18200409 | H22: =IFERROR(Historical_FS!H24/SUM(Historical_FS!H53:H55),0) -> 0.23824609 | I22: =IFERROR(Historical_FS!I24/SUM(Historical_FS!I53:I55),0) -> 0.20305158 | J22: =IFERROR(Historical_FS!J24/SUM(Historical_FS!J53:J55),0) -> 0.29352086 | K22: =IFERROR(Historical_FS!K24/SUM(Historical_FS!K53:K55),0) -> 0.30175563 | L22: =IFERROR(Historical_FS!L24/SUM(Historical_FS!L53:L55),0) -> 0.23292825 | N22: =IFERROR(AVERAGE(D22:L22),0) -> 0.21255607 | O22: =IFERROR(MEDIAN(D22:L22),0) -> 0.20305158
B23: Retained Earning% | D23: =IFERROR(Historical_FS!C50,0) -> 1 | E23: =IFERROR(Historical_FS!D50,0) -> 1 | F23: =IFERROR(Historical_FS!E50,0) -> 1 | G23: =IFERROR(Historical_FS!F50,0) -> 1 | H23: =IFERROR(Historical_FS!G50,0) -> 1 | I23: =IFERROR(Historical_FS!H50,0) -> 1 | J23: =IFERROR(Historical_FS!I50,0) -> 0.9305032 | K23: =IFERROR(Historical_FS!J50,0) -> 1 | L23: =IFERROR(Historical_FS!K50,0) -> 0.96697819 | N23: =IFERROR(AVERAGE(D23:L23),0) -> 0.98860904 | O23: =IFERROR(MEDIAN(D23:L23),0) -> 1
B24: Return On Equity% | D24: =IFERROR(Historical_FS!D39/SUM(Historical_FS!D53:D54),0) -> 0.25663139 | E24: =IFERROR(Historical_FS!E39/SUM(Historical_FS!E53:E54),0) -> 0.13766822 | F24: =IFERROR(Historical_FS!F39/SUM(Historical_FS!F53:F54),0) -> 0.20924968 | G24: =IFERROR(Historical_FS!G39/SUM(Historical_FS!G53:G54),0) -> 0.092578087 | H24: =IFERROR(Historical_FS!H39/SUM(Historical_FS!H53:H54),0) -> 0.21295441 | I24: =IFERROR(Historical_FS!I39/SUM(Historical_FS!I53:I54),0) -> 0.19280116 | J24: =IFERROR(Historical_FS!J39/SUM(Historical_FS!J53:J54),0) -> 0.23266811 | K24: =IFERROR(Historical_FS!K39/SUM(Historical_FS!K53:K54),0) -> 0.23930222 | L24: =IFERROR(Historical_FS!L39/SUM(Historical_FS!L53:L54),0) -> 0.18525896 | N24: =IFERROR(AVERAGE(D24:L24),0) -> 0.19545691 | O24: =IFERROR(MEDIAN(D24:L24),0) -> 0.20924968
B25: Self Sustained Growth Rate% | D25: =D23*D24 -> 0.25663139 | E25: =E23*E24 -> 0.13766822 | F25: =F23*F24 -> 0.20924968 | G25: =G23*G24 -> 0.092578087 | H25: =H23*H24 -> 0.21295441 | I25: =I23*I24 -> 0.19280116 | J25: =J23*J24 -> 0.21649842 | K25: =K23*K24 -> 0.23930222 | L25: =L23*L24 -> 0.17914138 | N25: =IFERROR(AVERAGE(D25:L25),0) -> 0.19298055 | O25: =IFERROR(MEDIAN(D25:L25),0) -> 0.20924968
B26: Interest Coverage Ratio | D26: =IFERROR(Historical_FS!D24/Historical_FS!D27,0) -> 4.00499 | E26: =IFERROR(Historical_FS!E24/Historical_FS!E27,0) -> 5.025974 | F26: =IFERROR(Historical_FS!F24/Historical_FS!F27,0) -> 5.4303243 | G26: =IFERROR(Historical_FS!G24/Historical_FS!G27,0) -> 5.3889908 | H26: =IFERROR(Historical_FS!H24/Historical_FS!H27,0) -> 12.61794 | I26: =IFERROR(Historical_FS!I24/Historical_FS!I27,0) -> 10.265645 | J26: =IFERROR(Historical_FS!J24/Historical_FS!J27,0) -> 16.461538 | K26: =IFERROR(Historical_FS!K24/Historical_FS!K27,0) -> 50.755486 | L26: =IFERROR(Historical_FS!L24/Historical_FS!L27,0) -> 38.655502 | N26: =IFERROR(AVERAGE(D26:L26),0) -> 16.511821 | O26: =IFERROR(MEDIAN(D26:L26),0) -> 10.265645
B28: Debtor Turnover Ratio | D28: =IFERROR(Historical_FS!D6/Historical_FS!D65,0) -> 6.2747815 | E28: =IFERROR(Historical_FS!E6/Historical_FS!E65,0) -> 5.9269359 | F28: =IFERROR(Historical_FS!F6/Historical_FS!F65,0) -> 5.8358039 | G28: =IFERROR(Historical_FS!G6/Historical_FS!G65,0) -> 5.2883625 | H28: =IFERROR(Historical_FS!H6/Historical_FS!H65,0) -> 4.8614152 | I28: =IFERROR(Historical_FS!I6/Historical_FS!I65,0) -> 5.5514861 | J28: =IFERROR(Historical_FS!J6/Historical_FS!J65,0) -> 7.565594 | K28: =IFERROR(Historical_FS!K6/Historical_FS!K65,0) -> 5.6743435 | L28: =IFERROR(Historical_FS!L6/Historical_FS!L65,0) -> 5.0284018 | N28: =IFERROR(AVERAGE(D28:L28),0) -> 5.7785694 | O28: =IFERROR(MEDIAN(D28:L28),0) -> 5.6743435
B29: Creditor Turnover Ratio | D29: =IFERROR(Historical_FS!D6/Historical_FS!D56,0) -> 6.9047619 | E29: =IFERROR(Historical_FS!E6/Historical_FS!E56,0) -> 6.0810617 | F29: =IFERROR(Historical_FS!F6/Historical_FS!F56,0) -> 7.244731 | G29: =IFERROR(Historical_FS!G6/Historical_FS!G56,0) -> 6.3692117 | H29: =IFERROR(Historical_FS!H6/Historical_FS!H56,0) -> 5.4153586 | I29: =IFERROR(Historical_FS!I6/Historical_FS!I56,0) -> 7.0586661 | J29: =IFERROR(Historical_FS!J6/Historical_FS!J56,0) -> 12.038564 | K29: =IFERROR(Historical_FS!K6/Historical_FS!K56,0) -> 13.17308 | L29: =IFERROR(Historical_FS!L6/Historical_FS!L56,0) -> 12.08405 | N29: =IFERROR(AVERAGE(D29:L29),0) -> 8.4854983 | O29: =IFERROR(MEDIAN(D29:L29),0) -> 7.0586661
B30: Inventory Turnover Ratio | D30: =IFERROR(Historical_FS!D6/Historical_FS!D66,0) -> 5.4569892 | E30: =IFERROR(Historical_FS!E6/Historical_FS!E66,0) -> 5.7745232 | F30: =IFERROR(Historical_FS!F6/Historical_FS!F66,0) -> 6.9548543 | G30: =IFERROR(Historical_FS!G6/Historical_FS!G66,0) -> 6.9256706 | H30: =IFERROR(Historical_FS!H6/Historical_FS!H66,0) -> 6.6740431 | I30: =IFERROR(Historical_FS!I6/Historical_FS!I66,0) -> 4.9612491 | J30: =IFERROR(Historical_FS!J6/Historical_FS!J66,0) -> 5.9575147 | K30: =IFERROR(Historical_FS!K6/Historical_FS!K66,0) -> 6.2987872 | L30: =IFERROR(Historical_FS!L6/Historical_FS!L66,0) -> 5.5332506 | N30: =IFERROR(AVERAGE(D30:L30),0) -> 6.0596536 | O30: =IFERROR(MEDIAN(D30:L30),0) -> 5.9575147
B31: Fixed Asset Turnover Ratio | D31: =IFERROR(Historical_FS!D6/Historical_FS!D59,0) -> 3.6941516 | E31: =IFERROR(Historical_FS!E6/Historical_FS!E59,0) -> 1.8262509 | F31: =IFERROR(Historical_FS!F6/Historical_FS!F59,0) -> 1.9729301 | G31: =IFERROR(Historical_FS!G6/Historical_FS!G59,0) -> 2.3706078 | H31: =IFERROR(Historical_FS!H6/Historical_FS!H59,0) -> 2.553136 | I31: =IFERROR(Historical_FS!I6/Historical_FS!I59,0) -> 3.6892905 | J31: =IFERROR(Historical_FS!J6/Historical_FS!J59,0) -> 5.5424064 | K31: =IFERROR(Historical_FS!K6/Historical_FS!K59,0) -> 5.2221207 | L31: =IFERROR(Historical_FS!L6/Historical_FS!L59,0) -> 5.7839531 | N31: =IFERROR(AVERAGE(D31:L31),0) -> 3.6283163 | O31: =IFERROR(MEDIAN(D31:L31),0) -> 3.6892905
B32: Capital Turnover Ratio | D32: =IFERROR(Historical_FS!D6/SUM(Historical_FS!D53:D54),0) -> 3.8462041 | E32: =IFERROR(Historical_FS!E6/SUM(Historical_FS!E53:E54),0) -> 2.3282065 | F32: =IFERROR(Historical_FS!F6/SUM(Historical_FS!F53:F54),0) -> 2.482859 | G32: =IFERROR(Historical_FS!G6/SUM(Historical_FS!G53:G54),0) -> 2.2625575 | H32: =IFERROR(Historical_FS!H6/SUM(Historical_FS!H53:H54),0) -> 1.8466189 | I32: =IFERROR(Historical_FS!I6/SUM(Historical_FS!I53:I54),0) -> 2.0836493 | J32: =IFERROR(Historical_FS!J6/SUM(Historical_FS!J53:J54),0) -> 2.3088096 | K32: =IFERROR(Historical_FS!K6/SUM(Historical_FS!K53:K54),0) -> 1.7035933 | L32: =IFERROR(Historical_FS!L6/SUM(Historical_FS!L53:L54),0) -> 1.5587877 | N32: =IFERROR(AVERAGE(D32:L32),0) -> 2.2690318 | O32: =IFERROR(MEDIAN(D32:L32),0) -> 2.2625575
B34: Debtor Days | D34: =IFERROR(365/D28,0) -> 58.169356 | E34: =IFERROR(365/E28,0) -> 61.583255 | F34: =IFERROR(365/F28,0) -> 62.544939 | G34: =IFERROR(365/G28,0) -> 69.019474 | H34: =IFERROR(365/H28,0) -> 75.081017 | I34: =IFERROR(365/I28,0) -> 65.748161 | J34: =IFERROR(365/J28,0) -> 48.244725 | K34: =IFERROR(365/K28,0) -> 64.324621 | L34: =IFERROR(365/L28,0) -> 72.587675 | N34: =IFERROR(AVERAGE(D34:L34),0) -> 64.144803 | O34: =IFERROR(MEDIAN(D34:L34),0) -> 64.324621
B35: Creditor Days | D35: =IFERROR(365/D29,0) -> 52.862069 | E35: =IFERROR(365/E29,0) -> 60.022414 | F35: =IFERROR(365/F29,0) -> 50.381442 | G35: =IFERROR(365/G29,0) -> 57.306935 | H35: =IFERROR(365/H29,0) -> 67.400893 | I35: =IFERROR(365/I29,0) -> 51.709487 | J35: =IFERROR(365/J29,0) -> 30.319232 | K35: =IFERROR(365/K29,0) -> 27.708023 | L35: =IFERROR(365/L29,0) -> 30.205104 | N35: =IFERROR(AVERAGE(D35:L35),0) -> 47.546178 | O35: =IFERROR(MEDIAN(D35:L35),0) -> 51.709487
B36: Inventory Days | D36: =IFERROR(365/D30,0) -> 66.8867 | E36: =IFERROR(365/E30,0) -> 63.208682 | F36: =IFERROR(365/F30,0) -> 52.48133 | G36: =IFERROR(365/G30,0) -> 52.702478 | H36: =IFERROR(365/H30,0) -> 54.689488 | I36: =IFERROR(365/I30,0) -> 73.570183 | J36: =IFERROR(365/J30,0) -> 61.267159 | K36: =IFERROR(365/K30,0) -> 57.947663 | L36: =IFERROR(365/L30,0) -> 65.964842 | N36: =IFERROR(AVERAGE(D36:L36),0) -> 60.968725 | O36: =IFERROR(MEDIAN(D36:L36),0) -> 61.267159
B38: CFO/Sales | D38: =IFERROR(Historical_FS!D85/Historical_FS!D6,0) -> 0.04416511 | E38: =IFERROR(Historical_FS!E85/Historical_FS!E6,0) -> 0.011796626 | F38: =IFERROR(Historical_FS!F85/Historical_FS!F6,0) -> -0.026051843 | G38: =IFERROR(Historical_FS!G85/Historical_FS!G6,0) -> 0.15795737 | H38: =IFERROR(Historical_FS!H85/Historical_FS!H6,0) -> 0.1605739 | I38: =IFERROR(Historical_FS!I85/Historical_FS!I6,0) -> -0.098581937 | J38: =IFERROR(Historical_FS!J85/Historical_FS!J6,0) -> 0.0073519372 | K38: =IFERROR(Historical_FS!K85/Historical_FS!K6,0) -> 0.084237703 | L38: =IFERROR(Historical_FS!L85/Historical_FS!L6,0) -> 0.070237735 | N38: =IFERROR(AVERAGE(D38:L38),0) -> 0.045742956 | O38: =IFERROR(MEDIAN(D38:L38),0) -> 0.04416511
B39: CFO/EBITDA | D39: =IFERROR(Historical_FS!D85/Historical_FS!D18,0) -> 0.28365699 | E39: =IFERROR(Historical_FS!E85/Historical_FS!E18,0) -> 0.080759136 | F39: =IFERROR(Historical_FS!F85/Historical_FS!F18,0) -> -0.14968193 | G39: =IFERROR(Historical_FS!G85/Historical_FS!G18,0) -> 0.91570497 | H39: =IFERROR(Historical_FS!H85/Historical_FS!H18,0) -> 0.77691454 | I39: =IFERROR(Historical_FS!I85/Historical_FS!I18,0) -> -0.62717098 | J39: =IFERROR(Historical_FS!J85/Historical_FS!J18,0) -> 0.045216717 | K39: =IFERROR(Historical_FS!K85/Historical_FS!K18,0) -> 0.41809198 | L39: =IFERROR(Historical_FS!L85/Historical_FS!L18,0) -> 0.38824481 | N39: =IFERROR(AVERAGE(D39:L39),0) -> 0.23685958 | O39: =IFERROR(MEDIAN(D39:L39),0) -> 0.28365699
B40: CFO/Total Asset | D40: =IFERROR(Historical_FS!D85/Historical_FS!D70,0) -> 0.042881647 | E40: =IFERROR(Historical_FS!E85/Historical_FS!E70,0) -> 0.01218769 | F40: =IFERROR(Historical_FS!F85/Historical_FS!F70,0) -> -0.027387881 | G40: =IFERROR(Historical_FS!G85/Historical_FS!G70,0) -> 0.18466987 | H40: =IFERROR(Historical_FS!H85/Historical_FS!H70,0) -> 0.18901272 | I40: =IFERROR(Historical_FS!I85/Historical_FS!I70,0) -> -0.13285098 | J40: =IFERROR(Historical_FS!J85/Historical_FS!J70,0) -> 0.013001244 | K40: =IFERROR(Historical_FS!K85/Historical_FS!K70,0) -> 0.12707319 | L40: =IFERROR(Historical_FS!L85/Historical_FS!L70,0) -> 0.092483173 | N40: =IFERROR(AVERAGE(D40:L40),0) -> 0.055674519 | O40: =IFERROR(MEDIAN(D40:L40),0) -> 0.042881647
B41: CFO/Total Debt | D41: =IFERROR(Historical_FS!D85/Historical_FS!D55,0) -> 0.070652174 | E41: =IFERROR(Historical_FS!E85/Historical_FS!E55,0) -> 0.031545741 | F41: =IFERROR(Historical_FS!F85/Historical_FS!F55,0) -> -0.063475271 | G41: =IFERROR(Historical_FS!G85/Historical_FS!G55,0) -> 0.61613774 | H41: =IFERROR(Historical_FS!H85/Historical_FS!H55,0) -> 1.3017751 | I41: =IFERROR(Historical_FS!I85/Historical_FS!I55,0) -> -0.81843364 | J41: =IFERROR(Historical_FS!J85/Historical_FS!J55,0) -> 0.14915832 | K41: =IFERROR(Historical_FS!K85/Historical_FS!K55,0) -> 0 | L41: =IFERROR(Historical_FS!L85/Historical_FS!L55,0) -> 1.9961187 | N41: =IFERROR(AVERAGE(D41:L41),0) -> 0.36483099 | O41: =IFERROR(MEDIAN(D41:L41),0) -> 0.070652174

Sheet Forecasting
B3: ="Sales Forecasting -" &DataSheet!B1 -> Sales Forecasting -STYLAM INDUSTRIES LTD
B4: Year Weight | C4: Year | D4: Sales | E4: Sales Growth
B5: 1 | C5: {=Historical_FS!C3:L3} -> 42460 | D5: {=TRANSPOSE(Historical_FS!C6:L6)} -> 264.26
B6: =B5+1 -> 2 | C6: =C5+365 -> 42825 | D6: 294.35 | E6: =D6/D5-1 -> 0.11386513
B7: =B6+1 -> 3 | C7: =C6+365 -> 43190 | D7: 339.08 | E7: =D7/D6-1 -> 0.15196195
B8: =B7+1 -> 4 | C8: =C7+365 -> 43555 | D8: 460.62 | E8: =D8/D7-1 -> 0.35844049
B9: =B8+1 -> 5 | C9: =C8+365 -> 43920 | D9: 462.15 | E9: =D9/D8-1 -> 0.00332161
B10: =B9+1 -> 6 | C10: =C9+365 -> 44285 | D10: 479.53 | E10: =D10/D9-1 -> 0.037606838
B11: =B10+1 -> 7 | C11: =C10+365 -> 44650 | D11: 659.35 | E11: =D11/D10-1 -> 0.37499218
B12: =B11+1 -> 8 | C12: =C11+365 -> 45015 | D12: 952.13 | E12: =D12/D11-1 -> 0.44404338
B13: =B12+1 -> 9 | C13: =C12+365 -> 45380 | D13: 914.08 | E13: =D13/D12-1 -> -0.03996303
B14: =B13+1 -> 10 | C14: =C13+365 -> 45745 | D14: 1025.09 | E14: =D14/D13-1 -> 0.12144451
B15: =B14+1 -> 11 | C15: =C14+365 -> 46110 | D15: =FORECAST(B15,$D$5:$D$14,$B$5:$B$14) -> 1080.544 | E15: =D15/D14-1 -> 0.054096713 | H15: SUMMARY OUTPUT
B16: =B15+1 -> 12 | C16: =C15+365 -> 46475 | D16: =FORECAST(B16,$D$5:$D$14,$B$5:$B$14) -> 1170.6313 | E16: =D16/D15-1 -> 0.083372147
B17: =B16+1 -> 13 | C17: =C16+365 -> 46840 | D17: =FORECAST(B17,$D$5:$D$14,$B$5:$B$14) -> 1260.7185 | E17: =D17/D16-1 -> 0.076956147 | H17: Regression Statistics
B18: =B17+1 -> 14 | C18: =C17+365 -> 47205 | D18: =FORECAST(B18,$D$5:$D$14,$B$5:$B$14) -> 1350.8058 | E18: =D18/D17-1 -> 0.071457085 | H18: Multiple R | I18: 0.95652046
B19: =B18+1 -> 15 | C19: =C18+365 -> 47570 | D19: =FORECAST(B19,$D$5:$D$14,$B$5:$B$14) -> 1440.8931 | E19: =D19/D18-1 -> 0.066691505 | H19: R Square | I19: 0.9149314
H20: Adjusted R Square | I20: 0.90429782
H21: Standard Error | I21: 88.213653
H22: Observations | I22: 10
H24: ANOVA
I25: df | J25: SS | K25: MS | L25: F | M25: Significance F
H26: Regression | I26: 1 | J26: 669546.63 | K26: 669546.63 | L26: 86.041745 | M26: 1.4834601e-05
H27: Residual | I27: 8 | J27: 62253.189 | K27: 7781.6486
H28: Total | I28: 9 | J28: 731799.82
I30: Coefficients | J30: Standard Error | K30: t Stat | L30: P-value | M30: Lower 95% | N30: Upper 95% | O30: Lower 95.0% | P30: Upper 95.0%
H31: Intercept | I31: 89.584 | J31: 60.261397 | K31: 1.4865902 | L31: 0.17543341 | M31: -49.379032 | N31: 228.54703 | O31: -49.379032 | P31: 228.54703
H32: X Variable 1 | I32: 90.087273 | J32: 9.7120036 | K32: 9.275869 | L32: 1.4834601e-05 | M32: 67.691352 | N32: 112.48319 | O32: 67.691352 | P32: 112.48319

Sheet WACC
B2: Weighted Averae Cost of Capital
B3: All figures are in INR Cr.
B5: Peer Comps
H7: Debt/ | I7: Debt/ | J7: Levered | K7: Unlevered
B8: Name of The Company | D8: Country | E8: Total Debt | F8: Total Equity | G8: Tax Rate1 | H8: Equity | I8: Capital | J8: Beta2 | K8: Beta3
B10: ='Beta- Comps'!C3 -> Century Plyboard | D10: India | E10: ='Beta- Comps'!D3 -> 1643.25 | F10: ='Beta- Comps'!F3 -> 16428.58 | G10: 0.3 | H10: ='Beta- Comps'!E3 -> 0.67 | I10: =E10/F10 -> 0.10002386 | J10: ='Beta- Comps'!G3 -> 1.61 | K10: =J10/(1+(1-G10)*H10) -> 1.0959837
B11: ='Beta- Comps'!C4 -> Greenlam Industr | D11: India | E11: ='Beta- Comps'!D4 -> 1171.06 | F11: ='Beta- Comps'!F4 -> 6378.69 | G11: 0.3 | H11: ='Beta- Comps'!E4 -> 1.03 | I11: =E11/F11 -> 0.18358942 | J11: ='Beta- Comps'!G4 -> 0.63 | K11: =J11/(1+(1-G11)*H11) -> 0.36606624
B12: ='Beta- Comps'!C5 -> Stylam Industrie | D12: India | E12: ='Beta- Comps'!D5 -> 0 | F12: ='Beta- Comps'!F5 -> 3688.41 | G12: 0.3 | H12: ='Beta- Comps'!E5 -> 0 | I12: =E12/F12 -> 0 | J12: ='Beta- Comps'!G5 -> 0.76064797 | K12: =J12*(1+(1-G12)*H12) -> 0.76064797
B13: ='Beta- Comps'!C6 -> Greenply Industr | D13: India | E13: ='Beta- Comps'!D6 -> 542.3 | F13: ='Beta- Comps'!F6 -> 2721.93 | G13: 0.3 | H13: ='Beta- Comps'!E6 -> 0.64 | I13: =E13/F13 -> 0.19923363 | J13: ='Beta- Comps'!G6 -> 1.33 | K13: =J13/(1+(1-G13)*H13) -> 0.91850829
B14: ='Beta- Comps'!C7 -> Greenpanel Inds. | D14: India | E14: ='Beta- Comps'!D7 -> 412.63 | F14: ='Beta- Comps'!F7 -> 2577.01 | G14: 0.3 | H14: ='Beta- Comps'!E7 -> 0.3 | I14: =E14/F14 -> 0.16011967 | J14: 1.21 | K14: =J14/(1+(1-G14)*H14) -> 1
G16: Average | H16: =MEDIAN(H9:H13) -> 0.655 | I16: =MEDIAN(I9:I13) -> 0.14180664 | J16: =MEDIAN(J9:J13) -> 1.045324 | K16: =MEDIAN(K9:K13) -> 0.83957813
G17: Median | H17: =MEDIAN(H10:H14) -> 0.64 | I17: =MEDIAN(I10:I14) -> 0.16011967 | J17: =MEDIAN(J10:J14) -> 1.21 | K17: =MEDIAN(K10:K14) -> 0.91850829
B20: Cost of Debt | G20: Cost of Equity
B22: Pre-Tax Cost of Debt | E22: 0 | G22: Risk Free Rate | K22: 0.0596 | L22: 10 year goernment bond - country default spread
B23: Tax Rate | E23: 0 | G23: Equity Risk Premium | K23: =Rm!H7-WACC!K22 -> 0.10469231
B24: Post Tax Cost of Debt | E24: 0 | G24: Levered Beta4 | K24: =K32 -> 1.0247494
G25: Cost of Equity | K25: =K22+K23*K24 -> 0.16688338
B27: Capital Structure | G27: Levered Beta
D29: Current | E29: Target | G29: Comps Median Unlevered Beta | K29: =K17 -> 0.91850829
B30: Total Debt | C30: =E12 -> 0 | D30: =C30/$C$32 -> 0 | E30: =I16 -> 0.14180664 | G30: Target Debt/ Equity | K30: =E34 -> 0.16523857
B31: Market Capitalization | C31: =F12 -> 3688.41 | D31: =C31/$C$32 -> 1 | E31: =E32-E30 -> 0.85819336 | G31: Tax Rate | K31: =G12 -> 0.3
B32: Total Capital | C32: =SUM(C30:C31) -> 3688.41 | D32: =C32/$C$32 -> 1 | E32: 1 | G32: Levered Beta | K32: =K29*(1+(1-K31)*K30) -> 1.0247494
B34: Debt / Equity | D34: =D30/D31 -> 0 | E34: =E30/E31 -> 0.16523857 | G34: Weighted Average Cost of Capital
G36: Cost of Equity | K36: =K25 -> 0.16688338
G37: Equity Weight | K37: =E31 -> 0.85819336
B39: Notes: | G39: Cost of Debt | K39: =E24 -> 0
B40: 1. Tax Rate considered as Marginal Tax Rate for the country | G40: Debt Weight | K40: =E30 -> 0.14180664
B41: 2.Levered beta is based on 5 year monthly data
B42: 3.Unlevered Beta = Levered Beta/(1+(1-Tax Rate)*Debt/Equity | G42: WACC | K42: =(K36*K37)+(K39*K40) -> 0.14321821
B43: 4.Unlevered Beta = Levered Beta/(1+(1- Tax Rate)*Debt/Equity)

Sheet Intrensic Growth
B2: ="Calculaation of ROIC - "&DataSheet!B1 -> Calculaation of ROIC - STYLAM INDUSTRIES LTD | D2: ='Data Room'!I3 -> 44256 | E2: ='Data Room'!J3 -> 44621 | F2: ='Data Room'!K3 -> 44986 | G2: ='Data Room'!L3 -> 45352 | H2: ='Data Room'!M3 -> 45717
B5: Current Asset
B6: Inventory | D6: ='Data Room'!I33 -> 67 | E6: ='Data Room'!J33 -> 72 | F6: ='Data Room'!K33 -> 133 | G6: ='Data Room'!L33 -> 160 | H6: ='Data Room'!M33 -> 145
B7: Trade Receivables | D7: ='Data Room'!I34 -> 87 | E7: ='Data Room'!J34 -> 99 | F7: ='Data Room'!K34 -> 119 | G7: ='Data Room'!L34 -> 126 | H7: ='Data Room'!M34 -> 161
B8: Loans n Advances | D8: ='Data Room'!I36 -> 4 | E8: ='Data Room'!J36 -> 4 | F8: ='Data Room'!K36 -> 18 | G8: ='Data Room'!L36 -> 14 | H8: ='Data Room'!M36 -> 13
B9: Other asset items | D9: ='Data Room'!I37 -> 24 | E9: ='Data Room'!J37 -> 28 | F9: ='Data Room'!K37 -> 31 | G9: ='Data Room'!L37 -> 26 | H9: ='Data Room'!M37 -> 36
B10: Total Current Asset | D10: =SUM(D6:D9) -> 182 | E10: =SUM(E6:E9) -> 203 | F10: =SUM(F6:F9) -> 301 | G10: =SUM(G6:G9) -> 326 | H10: =SUM(H6:H9) -> 355
B12: Curent Liabilities
B13: Trade Payables | D13: ='Data Room'!I11 -> 36 | E13: ='Data Room'!J11 -> 51 | F13: ='Data Room'!K11 -> 58 | G13: ='Data Room'!L11 -> 40 | H13: ='Data Room'!M11 -> 38
B14: Advance from Customers | D14: ='Data Room'!I12 -> 5 | E14: ='Data Room'!J12 -> 4 | F14: ='Data Room'!K12 -> 9 | G14: ='Data Room'!L12 -> 4 | H14: ='Data Room'!M12 -> 5
B15: Other liability items | D15: ='Data Room'!I13 -> 33 | E15: ='Data Room'!J13 -> 33 | F15: ='Data Room'!K13 -> 27 | G15: ='Data Room'!L13 -> 35 | H15: ='Data Room'!M13 -> 27
B16: Total Current Liabilities | D16: =SUM(D13:D15) -> 74 | E16: =SUM(E13:E15) -> 88 | F16: =SUM(F13:F15) -> 94 | G16: =SUM(G13:G15) -> 79 | H16: =SUM(H13:H15) -> 70
A18: # | B18: Net Working Capital | D18: =D10-D16 -> 108 | E18: =E10-E16 -> 115 | F18: =F10-F16 -> 207 | G18: =G10-G16 -> 247 | H18: =H10-H16 -> 285
B20: Fixed Assets-
B21: Land | D21: ='Data Room'!I17 -> 20.15 | E21: ='Data Room'!J17 -> 20.15 | F21: ='Data Room'!K17 -> 26.09 | G21: ='Data Room'!L17 -> 26.3 | H21: ='Data Room'!M17 -> 25.94
B22: Building | D22: ='Data Room'!I18 -> 50.99 | E22: ='Data Room'!J18 -> 50.99 | F22: ='Data Room'!K18 -> 50.99 | G22: ='Data Room'!L18 -> 50.99 | H22: ='Data Room'!M18 -> 51.28
B23: Plant Machinery | D23: ='Data Room'!I19 -> 182.65 | E23: ='Data Room'!J19 -> 196.08 | F23: ='Data Room'!K19 -> 201.67 | G23: ='Data Room'!L19 -> 213.13 | H23: ='Data Room'!M19 -> 237.58
B24: Equipments | D24: ='Data Room'!I20 -> 11.41 | E24: ='Data Room'!J20 -> 11.43 | F24: ='Data Room'!K20 -> 11.56 | G24: ='Data Room'!L20 -> 11.59 | H24: ='Data Room'!M20 -> 11.7
B25: Computers | D25: ='Data Room'!I21 -> 2.02 | E25: ='Data Room'!J21 -> 2.14 | F25: ='Data Room'!K21 -> 2.28 | G25: ='Data Room'!L21 -> 2.43 | H25: ='Data Room'!M21 -> 2.56
B26: Furniture n fittings | D26: ='Data Room'!I22 -> 2.83 | E26: ='Data Room'!J22 -> 2.83 | F26: ='Data Room'!K22 -> 2.87 | G26: ='Data Room'!L22 -> 3.1 | H26: ='Data Room'!M22 -> 3.18
B27: Vehicles | D27: ='Data Room'!I23 -> 8.3 | E27: ='Data Room'!J23 -> 8.21 | F27: ='Data Room'!K23 -> 8.63 | G27: ='Data Room'!L23 -> 9.36 | H27: ='Data Room'!M23 -> 9.05
B28: Intangible Assets | D28: ='Data Room'!I24 -> 0 | E28: ='Data Room'!J24 -> 0 | F28: ='Data Room'!K24 -> 0 | G28: ='Data Room'!L24 -> 0 | H28: ='Data Room'!M24 -> 0
B29: Other fixed assets | D29: ='Data Room'!I25 -> 4.76 | E29: ='Data Room'!J25 -> 4.75 | F29: ='Data Room'!K25 -> 5.88 | G29: ='Data Room'!L25 -> 5.87 | H29: ='Data Room'!M25 -> 5.95
B30: Gross Block | D30: =SUM(D21:D29) -> 283.11 | E30: =SUM(E21:E29) -> 296.58 | F30: =SUM(F21:F29) -> 309.97 | G30: =SUM(G21:G29) -> 322.77 | H30: =SUM(H21:H29) -> 347.24
B31: Accumulated Depreciation | D31: =-'Data Room'!I28 -> -88.15 | E31: =-'Data Room'!J28 -> -108.76 | F31: =-'Data Room'!K28 -> -131.24 | G31: =-'Data Room'!L28 -> -150.98 | H31: =-'Data Room'!M28 -> -172.2
A32: # | B32: Net Non Current Assets | D32: =SUM(D30:D31) -> 194.96 | E32: =SUM(E30:E31) -> 187.82 | F32: =SUM(F30:F31) -> 178.73 | G32: =SUM(G30:G31) -> 171.79 | H32: =SUM(H30:H31) -> 175.04
A34: # | B34: Invested Capital | D34: =D32+D18 -> 302.96 | E34: =E32+E18 -> 302.82 | F34: =F32+F18 -> 385.73 | G34: =G32+G18 -> 418.79 | H34: =H32+H18 -> 460.04
B35: EBIT | D35: =Historical_FS!H24 -> 75.96 | E35: =Historical_FS!I24 -> 80.38 | F35: =Historical_FS!J24 -> 134.82 | G35: =Historical_FS!K24 -> 161.91 | H35: =Historical_FS!L24 -> 161.58
A37: # | B37: ROIC | D37: =D35/D34 -> 0.25072617 | E37: =E35/E34 -> 0.26543821 | F37: =F35/F34 -> 0.34951909 | G37: =G35/G34 -> 0.38661382 | H37: =H35/H34 -> 0.35123033
B40: Calculation of Reinvestment Rate | D40: =D2 -> 44256 | E40: =E2 -> 44621 | F40: =F2 -> 44986 | G40: =G2 -> 45352 | H40: =H2 -> 45717
B42: Net CapEx | D42: =-SUM('Data Room'!I56:I57) -> 24 | E42: =-SUM('Data Room'!J56:J57) -> 6 | F42: =-SUM('Data Room'!K56:K57) -> 13 | G42: =-SUM('Data Room'!L56:L57) -> 26 | H42: =-SUM('Data Room'!M56:M57) -> 14
B43: Changew in Working Capital | E43: =E18-D18 -> 7 | F43: =F18-E18 -> 92 | G43: =G18-F18 -> 40 | H43: =H18-G18 -> 38
B45: EBIT | D45: =D35 -> 75.96 | E45: =E35 -> 80.38 | F45: =F35 -> 134.82 | G45: =G35 -> 161.91 | H45: =H35 -> 161.58
B46: Marginal Tax Rate | D46: 0.25 | E46: 0.25 | F46: 0.25 | G46: 0.25 | H46: 0.25
B47: EBIT (1- Tax) | D47: =D45*(1-D46) -> 56.97 | E47: =E45*(1-E46) -> 60.285 | F47: =F45*(1-F46) -> 101.115 | G47: =G45*(1-G46) -> 121.4325 | H47: =H45*(1-H46) -> 121.185
B49: Reinvestment | E49: =SUM(E42:E43) -> 13 | F49: =SUM(F42:F43) -> 105 | G49: =SUM(G42:G43) -> 66 | H49: =SUM(H42:H43) -> 52
B51: Reinvestmeant Rate | E51: =E49/E47 -> 0.21564237 | F51: =F49/F47 -> 1.0384216 | G51: =G49/G47 -> 0.54351183 | H51: =H49/H47 -> 0.42909601
G53: 4 Year Average | I53: =AVERAGE(E51:H51) -> 0.55666795
G54: 4 year Median | I54: =MEDIAN(E51:H51) -> 0.48630392
B56: Calculation of Growth Rate | D56: =D40 -> 44256 | E56: =E40 -> 44621 | F56: =F40 -> 44986 | G56: =G40 -> 45352 | H56: =H40 -> 45717
...

Sheet DCF
B2: Calculation of FCFF | D2: ='Intrensic Growth'!H2 -> 45717 | E2: =D2+366 -> 46083 | F2: =E2+366 -> 46449 | G2: =F2+366 -> 46815 | H2: =G2+366 -> 47181 | I2: =H2+366 -> 47547
B4: EBIT | D4: =Historical_FS!L24 -> 161.58 | E4: =D4*(1+$D$14) -> 190.73232 | F4: =E4*(1+$D$14) -> 225.14431 | G4: =F4*(1+$D$14) -> 265.76493 | H4: =G4*(1+$D$14) -> 313.71434 | I4: =H4*(1+$D$14) -> 370.31479
B5: Tax Rate | D5: 0.25 | E5: 0.25 | F5: 0.25 | G5: 0.25 | H5: 0.25 | I5: 0.25
B6: EBIT(1-T) | D6: =D4*(1-D5) -> 121.185 | E6: =E4*(1-E5) -> 143.04924 | F6: =F4*(1-F5) -> 168.85824 | G6: =G4*(1-G5) -> 199.3237 | H6: =H4*(1-H5) -> 235.28575 | I6: =I4*(1-I5) -> 277.73609
B7: less: Reinvestment Rate | D7: ='Intrensic Growth'!I54 -> 0.48630392 | E7: =D7 -> 0.48630392 | F7: =E7 -> 0.48630392 | G7: =F7 -> 0.48630392 | H7: =G7 -> 0.48630392 | I7: =H7 -> 0.48630392
B8: Free Cash Flow to Firm (FCFF) | D8: =D6*(1-D7) -> 62.25226 | E8: =E6*(1-E7) -> 73.483834 | F8: =F6*(1-F7) -> 86.741814 | G8: =G6*(1-G7) -> 102.3918 | H8: =H6*(1-H7) -> 120.86537 | I8: =I6*(1-I7) -> 142.67194
B9: Mid Year Convention | E9: 0.5 | F9: =E9+1 -> 1.5 | G9: =F9+1 -> 2.5 | H9: =G9+1 -> 3.5 | I9: =H9+1 -> 4.5
B10: Discounting Factor | E10: =1/(1+$D$16)^E9 -> 0.93526662 | F10: =1/(1+$D$16)^F9 -> 0.81809983 | G10: =1/(1+$D$16)^G9 -> 0.71561127 | H10: =1/(1+$D$16)^H9 -> 0.6259621 | I10: =1/(1+$D$16)^I9 -> 0.54754385
B12: PV of FCFF | E12: =E8*E10 -> 68.726977 | F12: =F8*F10 -> 70.963463 | G12: =G8*G10 -> 73.272728 | H12: =H8*H10 -> 75.65714 | I12: =I8*I10 -> 78.119144
B14: Expected Growth | D14: ='Intrensic Growth'!I64 -> 0.18042036
B15: Terminal Growth | D15: 0.065
B16: WACC | D16: =WACC!K42 -> 0.14321821
B18: Calculation of Terminal Value
B20: FCFF (n+1) | D20: =I8*(1+D14) -> 168.41286
B21: WACC | D21: =D16 -> 0.14321821
B22: Terminal Growth Ra | D22: =D15 -> 0.065
B24: Terminal Value | D24: =D20/(D21-D22) -> 2153.1159
B26: Calculation of Equity Value Per Share
B28: PV of FCFF | D28: =SUM(E12:I12) -> 366.73945
B29: PV of Terminal Value | D29: =D24*I10 -> 1178.9254
B30: Enterprise Value | D30: =SUM(D28:D29) -> 1545.6648
B32: Add: Cash | D32: =DataSheet!K69 -> 49.6
B33: Less: Debt | D33: =SUM(DataSheet!K59:K60) -> 120.9
B34: Value of Equity | D34: =D30+D32-D33 -> 1474.3648
B35: No of Shares | D35: =DataSheet!B6 -> 1.6947995
B37: Equity Value Per Share | D37: =D34/D35 -> 869.93463
B39: Share Price | D39: 2176
B40: Discount/Premium | D40: =D39/D37 -> 2.5013374 | E40: Premium

Sheet Data>

Sheet Data Room
B2: Balancesheet -
B3: Particulars | C3: 42064 | D3: 42430 | E3: 42795 | F3: 43160 | G3: 43525 | H3: 43891 | I3: 44256 | J3: 44621 | K3: 44986 | L3: 45352 | M3: 45717
B4: Equity Capital | C4: 7 | D4: 7 | E4: 7 | F4: 7 | G4: 8 | H4: 8 | I4: 8 | J4: 8 | K4: 8 | L4: 8 | M4: 8
B5: Reserves | C5: 27 | D5: 37 | E5: 49 | F5: 69 | G5: 137 | H5: 177 | I5: 196 | J5: 251 | K5: 308 | L5: 404 | M5: 528
B6: Borrowings - | C6: 73 | D6: 82 | E6: 117 | F6: 184 | G6: 127 | H6: 189 | I6: 118 | J6: 59 | K6: 79 | L6: 47 | M6: 0
B7: Long term Borrowings | C7: 29.43 | D7: 37.83 | E7: 62.77 | F7: 88.55 | G7: 42.36 | H7: 97.64 | I7: 35.65 | J7: 21.49 | K7: 9.14 | L7: 0.58 | M7: 0
B8: Short term Borrowings | C8: 40 | D8: 41.51 | E8: 48.91 | F8: 82.83 | G8: 74.23 | H8: 72.13 | I8: 58.53 | J8: 21.11 | K8: 55.94 | L8: 36.15 | M8: 0
B9: Other Borrowings | C9: 3.86 | D9: 2.39 | E9: 5.1 | F9: 12.62 | G9: 10.21 | H9: 19.28 | I9: 24.3 | J9: 16.55 | K9: 14.34 | L9: 10.2 | M9: 0
B10: Other Liabilities - | C10: 23 | D10: 24 | E10: 38 | F10: 43 | G10: 56 | H10: 64 | I10: 73 | J10: 89 | K10: 93 | L10: 79 | M10: 69
B11: Trade Payables | C11: 14 | D11: 13 | E11: 20 | F11: 18 | G11: 34 | H11: 27 | I11: 36 | J11: 51 | K11: 58 | L11: 40 | M11: 38
B12: Advance from Customers | C12: 1 | D12: 2 | E12: 3 | F12: 3 | G12: 2 | H12: 2 | I12: 5 | J12: 4 | K12: 9 | L12: 4 | M12: 5
B13: Other liability items | C13: 8 | D13: 9 | E13: 16 | F13: 21 | G13: 19 | H13: 35 | I13: 33 | J13: 33 | K13: 27 | L13: 35 | M13: 27
B14: Total Liabilities | C14: 131 | D14: 149 | E14: 211 | F14: 303 | G14: 328 | H14: 438 | I14: 395 | J14: 407 | K14: 489 | L14: 538 | M14: 606
... B39: Total Assets | C39: 131 | D39: 149 | E39: 211 | F39: 303 | G39: 328 | H39: 438 | I39: 395 | J39: 407 | K39: 489 | L39: 538 | M39: 606
B41: Cash Flow -
B42: Particulars | C42: 42064 | D42: 42430 | E42: 42795 | F42: 43160 | G42: 43525 | H42: 43891 | I42: 44256 | J42: 44621 | K42: 44986 | L42: 45352 | M42: 45717
B43: Cash from Operating Activity - | C43: 20 | D43: 6 | E43: 11 | F43: 26 | G43: 19 | H43: 28 | I43: 66 | J43: 79 | K43: 6 | L43: 66 | M43: 109
B44: Profit from operations | C44: 19 | D44: 23 | E44: 31 | F44: 45 | G44: 45 | H44: 78 | I44: 78 | J44: 98 | K44: 100 | L44: 151 | M44: 185
B45: Receivables | C45: -6 | D45: -7 | E45: -7 | F45: -10 | G45: -22 | H45: -23 | I45: -7 | J45: -14 | K45: -20 | L45: -7 | M45: -39
B46: Inventory | C46: 6 | D46: -1 | E46: -18 | F46: -11 | G46: -5 | H46: -5 | I46: 0 | J46: -5 | K46: -61 | L46: -27 | M46: 15
B47: Payables | C47: 6 | D47: -1 | E47: 7 | F47: 9 | G47: 12 | H47: -12 | I47: 13 | J47: 17 | K47: 10 | L47: -25 | M47: -4
B48: Loans Advances | C48: 3 | D48: -3 | E48: -4 | F48: 0 | G48: 0 | H48: 0 | I48: 0 | J48: 0 | K48: 0 | L48: 0 | M48: 0
B49: Other WC items | C49: -6 | D49: -1 | E49: 8 | F49: 0 | G49: 0 | H49: 0 | I49: 0 | J49: 0 | K49: 0 | L49: 0 | M49: -4
B50: Working capital changes | C50: 4 | D50: -14 | E50: -14 | F50: -12 | G50: -15 | H50: -41 | I50: 6 | J50: -2 | K50: -71 | L50: -59 | M50: -33
B52: Direct taxes | C52: -3 | D52: -3 | E52: -5 | F52: -8 | G52: -11 | H52: -9 | I52: -17 | J52: -17 | K52: -19 | L52: -26 | M52: -43
B53: Other operating items | C53: 0 | D53: 0 | E53: 0 | F53: 0 | G53: 0 | H53: 0 | I53: 0 | J53: 0 | K53: -4 | L53: 0 | M53: 0
B55: Cash from Investing Activity - | C55: -21 | D55: -12 | E55: -38 | F55: -77 | G55: -8 | H55: -53 | I55: 19 | J55: -6 | K55: -30 | L55: -12 | M55: -37
... B72: Net Cash Flow | C72: 2 | D72: -2 | E72: 0 | F72: 0 | G72: 0 | H72: -2 | I72: 5 | J72: 9 | K72: -7 | L72: 18 | M72: 68

Sheet DataSheet
A1: COMPANY NAME | B1: STYLAM INDUSTRIES LTD | E1: =IF(B2<>B3, "A NEW VERSION OF THE WORKSHEET IS AVAILABLE", "")
A2: LATEST VERSION | B2: 2.1 | E2: PLEASE DO NOT MAKE ANY CHANGES TO THIS SHEET
A3: CURRENT VERSION | B3: 2.1
A5: META
A6: Number of shares | B6: =IF(B9>0, B9/B8, 0) -> 1.6947995
A7: Face Value | B7: 5
A8: Current Price | B8: 2207.5
A9: Market Capitalization | B9: 3741.27
A15: PROFIT & LOSS
A16: Report Date | B16: 42460 | C16: 42825 | D16: 43190 | E16: 43555 | F16: 43921 | G16: 44286 | H16: 44651 | I16: 45016 | J16: 45382 | K16: 45747
A17: Sales | B17: 264.26 | C17: 294.35 | D17: 339.08 | E17: 460.62 | F17: 462.15 | G17: 479.53 | H17: 659.35 | I17: 952.13 | J17: 914.08 | K17: 1025.09
A18: Raw Material Cost | B18: 145.48 | C18: 153.79 | D18: 186.09 | E18: 260.76 | F18: 241.92 | G18: 251.48 | H18: 390.83 | I18: 554.16 | J18: 459.2 | K18: 562.25
A19: Change in Inventory | B19: 3.69 | C19: 0.29 | D19: 3.44 | E19: 0.77 | F19: -7.14 | G19: 4.93 | H19: 15.32 | I19: 23.16 | J19: -14.93 | K19: 4.89
A20: Power and Fuel | B20: 12.31 | C20: 14.06 | D20: 19.85 | E20: 29.16 | F20: 33 | G20: 23.63 | H20: 37.16 | I20: 52.72 | J20: 44.27 | K20: 46.49
A21: Other Mfr. Exp | B21: 19.42 | C21: 14.79 | D21: 23.27 | E21: 23.18 | F21: 24.11 | G21: 28.16 | H21: 27.2 | I21: 38.94 | J21: 43.56 | K21: 47.96
A22: Employee Cost | B22: 18.67 | C22: 26.61 | D22: 30.17 | E22: 30.3 | F22: 37.54 | G22: 38.25 | H22: 54.78 | I22: 68.75 | J22: 75.06 | K22: 83.54
A23: Selling and admin | B23: 42.69 | C23: 36.61 | D23: 30.06 | E23: 34.47 | F23: 35.25 | G23: 41.33 | H23: 57.39 | I23: 100.35 | J23: 91.05 | K23: 101.38
A24: Other Expenses | B24: -0.81 | C24: 2.95 | D24: 3.55 | E24: 3.35 | F24: 3.47 | G24: 2.5 | H24: 3.67 | I24: 5.56 | J24: 1.84 | K24: 2.91
A25: Other Income | B25: 0.6 | C25: 1.06 | D25: 2.06 | E25: 1.34 | F25: -14.33 | G25: 1.03 | H25: 7.92 | I25: 1.4 | J25: 5.55 | K25: 7.44
A26: Depreciation | B26: 4.65 | C26: 5.7 | D26: 10.83 | E26: 18.21 | F26: 20.98 | G26: 23.15 | H26: 23.26 | I26: 19.99 | J26: 22.26 | K26: 23.87
A27: Interest | B27: 6.46 | C27: 10.02 | D27: 7.7 | E27: 11.41 | F27: 10.9 | G27: 6.02 | H27: 7.83 | I27: 8.19 | J27: 3.19 | K27: 4.18
... A30: Net profit | B30: 12.15 | C30: 19.64 | D30: 20.06 | E30: 38.82 | F30: 18.91 | G30: 55.3 | H30: 61.01 | I30: 95.95 | J30: 128.4 | K30: 121.83
A31: Dividend Amount | H31: 4.24 | J31: 4.24
A40: Quarters
A41: Report Date | B41: 45107 | C41: 45199 | D41: 45291 | E41: 45382 | F41: 45473 | G41: 45565 | H41: 45657 | I41: 45747 | J41: 45838 | K41: 45930
A42: Sales | B42: 225.68 | C42: 233.94 | D42: 214.58 | E42: 239.88 | F42: 242.59 | G42: 262.7 | H42: 254.52 | I42: 265.28 | J42: 282.98 | K42: 292.4
A43: Expenses | B43: 183.91 | C43: 186.68 | D43: 166.78 | E43: 192.2 | F43: 200.73 | G43: 208.32 | H43: 208.53 | I43: 222.34 | J43: 230.05 | K43: 235.81
A44: Other Income | B44: 0.51 | C44: 1.89 | D44: 1.95 | E44: 0.17 | F44: 2.62 | G44: 1.9 | H44: 1.76 | I44: 1.16 | J44: 0.77 | K44: 0.91
A45: Depreciation | B45: 5.12 | C45: 5.26 | D45: 5.56 | E45: 6.33 | F45: 6.12 | G45: 5.43 | H45: 5.86 | I45: 6.45 | J45: 4.96 | K45: 4.82
A46: Interest | B46: 0.71 | C46: 0.61 | D46: 0.71 | E46: 0.47 | F46: 0.52 | G46: 4.02 | H46: -0.56 | I46: -0.07 | J46: 7.49 | K46: 1.87
A47: Profit before tax | B47: 36.45 | C47: 43.28 | D47: 43.48 | E47: 41.05 | F47: 37.84 | G47: 46.83 | H47: 42.45 | I47: 37.72 | J47: 41.25 | K47: 50.81
A48: Tax | B48: 8.69 | C48: 11.53 | D48: 12.17 | E48: 3.49 | F48: 9.5 | G48: 12.73 | H48: 12.04 | I48: 8.74 | J48: 12.99 | K48: 13.48
A49: Net profit | B49: 27.77 | C49: 31.74 | D49: 31.32 | E49: 37.56 | F49: 28.35 | G49: 34.1 | H49: 30.41 | I49: 28.97 | J49: 28.26 | K49: 37.33
A50: Operating Profit | B50: 41.77 | C50: 47.26 | D50: 47.8 | E50: 47.68 | F50: 41.86 | G50: 54.38 | H50: 45.99 | I50: 42.94 | J50: 52.93 | K50: 56.59
A55: BALANCE SHEET
A56: Report Date | B56: 42460 | C56: 42825 | D56: 43190 | E56: 43555 | F56: 43921 | G56: 44286 | H56: 44651 | I56: 45016 | J56: 45382 | K56: 45747
A57: Equity Share Capital | B57: 7.32 | C57: 7.32 | D57: 8.17 | E57: 8.17 | F57: 8.47 | G57: 8.47 | H57: 8.47 | I57: 8.47 | J57: 8.47 | K57: 8.47
A58: Reserves | B58: 48.88 | C58: 69.21 | D58: 137.47 | E58: 177.35 | F58: 195.79 | G58: 251.21 | H58: 307.97 | I58: 403.92 | J58: 528.09 | K58: 649.15
A59: Borrowings | B59: 116.78 | C59: 184 | D59: 126.8 | E59: 189.05 | F59: 118.48 | G59: 59.15 | H59: 79.42 | I59: 46.93 | K59: 36.07
A60: Other Liabilities | B60: 38.12 | C60: 42.63 | D60: 55.76 | E60: 63.58 | F60: 72.56 | G60: 88.55 | H60: 93.41 | I60: 79.09 | J60: 69.39 | K60: 84.83
...

Sheet BETA
B2: Regression Beta - 4 Years Daily
B4: Stylam Industries Limited | F4: Nifty50 | J4: Beta Drifting
B6: Date | C6: Closing Price | D6: Daily Return | F6: Date | G6: Closing Price | H6: Daily Return
B7: 46045 | C7: 2176.3 | F7: 46045 | G7: 25048.65
B8: 46044 | C8: 2205 | D8: =C8/C7-1 -> 0.01318752 | F8: 46044 | G8: 25289.9 | H8: =G8/G7-1 -> 0.0096312576 | J8: Levered Raw Beta | K8: =O11 -> 0.76064797
B9: 46043 | C9: 2175 | D9: =C9/C8-1 -> -0.013605442 | F9: 46043 | G9: 25157.5 | H9: =G9/G8-1 -> -0.0052352916 | J9: Raw Beta Weight | K9: 0.6
B10: 46042 | C10: 2169.9 | D10: =C10/C9-1 -> -0.0023448276 | F10: 46042 | G10: 25232.5 | H10: =G10/G9-1 -> 0.0029812183
B11: 46041 | C11: 2174 | D11: =C11/C10-1 -> 0.001889488 | F11: 46041 | G11: 25585.5 | H11: =G11/G10-1 -> 0.013989894 | J11: Market Beta | K11: 1 | N11: Beta | O11: =SLOPE(D6:D562,H6:H562) -> 0.76064797
B12: 46038 | C12: 2181.4 | D12: =C12/C11-1 -> 0.0034038638 | F12: 46038 | G12: 25694.35 | H12: =G12/G11-1 -> 0.0042543628 | J12: Market Beta Weight | K12: 0.4
B13: 46036 | C13: 2224.2 | D13: =C13/C12-1 -> 0.019620427 | F13: 46036 | G13: 25665.6 | H13: =G13/G12-1 -> -0.001118923
B14: 46035 | C14: 2188.6 | D14: =C14/C13-1 -> -0.016005755 | F14: 46035 | G14: 25732.3 | H14: =G14/G13-1 -> 0.0025988093 | J14: Adjusted Beta | K14: =(K8*K9)+(K11*K12) -> 0.85638878
B15: 46034 | C15: 2185.5 | D15: =C15/C14-1 -> -0.0014164306 | F15: 46034 | G15: 25790.25 | H15: =G15/G14-1 -> 0.0022520334
B16: 46031 | C16: 2175.1 | D16: =C16/C15-1 -> -0.0047586365 | F16: 46031 | G16: 25683.3 | H16: =G16/G15-1 -> -0.004146916
B17: 46030 | C17: 2183.6 | D17: =C17/C16-1 -> 0.0039078663 | F17: 46030 | G17: 25876.85 | H17: =G17/G16-1 -> 0.0075360254
B18: 46029 | C18: 2214.7 | D18: =C18/C17-1 -> 0.014242535 | F18: 46029 | G18: 26140.75 | H18: =G18/G17-1 -> 0.010198305
B19: 46028 | C19: 2197.6 | D19: =C19/C18-1 -> -0.007721136 | F19: 46028 | G19: 26178.7 | H19: =G19/G18-1 -> 0.0014517564 | N19: SUMMARY OUTPUT
B20: 46027 | C20: 2188.5 | D20: =C20/C19-1 -> -0.004140881 | F20: 46027 | G20: 26250.3 | H20: =G20/G19-1 -> 0.002735048
B21: 46024 | C21: 2207.8 | D21: =C21/C20-1 -> 0.0088188257 | F21: 46024 | G21: 26328.55 | H21: =G21/G20-1 -> 0.0029809183 | N21: Regression Statistics
B22: 46023 | C22: 2249.6 | D22: =C22/C21-1 -> 0.018932874 | F22: 46023 | G22: 26146.55 | H22: =G22/G21-1 -> -0.0069126481 | N22: Multiple R | O22: 0.24475611
B23: 46022 | C23: 2229.4 | D23: =C23/C22-1 -> -0.0089793741 | F23: 46022 | G23: 26129.6 | H23: =G23/G22-1 -> -0.00064826908 | N23: R Square | O23: 0.059905552
B24: 46021 | C24: 2175.1 | D24: =C24/C23-1 -> -0.024356329 | F24: 46021 | G24: 25938.85 | H24: =G24/G23-1 -> -0.00730015 | N24: Adjusted R Square | O24: 0.058202482
B25: 46020 | C25: 2174.3 | D25: =C25/C24-1 -> -0.00036779918 | F25: 46020 | G25: 25942.1 | H25: =G25/G24-1 -> 0.00012529468 | N25: Standard Error | O25: 0.024097208
