Workbook

Sheet MF_Analysis
C1: Academic Research
B3: Nippon India Growth Mid Cap Fund
B5: Analysis Report
C7: Fund and scheme details | I7: Top 10 stock holding by the fund
C9: Inception Date: | G9: 34967 | I9: BSE Ltd. | M9: 0.0352
C10: AUM (In Cr.) as on 17th Dec 2025: | G10: 42041 | I10: Fortis Healthcare Ltd. | M10: 0.0296
C11: Plan Type: | G11: Direct Growth Plan | I11: The Federal Bank Ltd. | M11: 0.0252
C12: Asset Class: | G12: Equity | I12: AU Small Finance Bank Ltd. | M12: 0.025
C13: Scheme Type Market Cap: | G13: Mid Cap | I13: Persistent Systems Ltd. | M13: 0.0248
C14: Benchmark: | G14: NIFTY Midcap 150 TRI | I14: Cholamandalam Financial Holdings Ltd. | M14: 0.0234
C15: Expense Ratio: | G15: 0.0073 | I15: Voltas Ltd. | M15: 0.0226
C16: Entry Load | G16: Nill | I16: Max Financial Services Ltd. | M16: 0.0206
C17: Exit Load: | G17: 0.01 | I17: Ashok Leyland Ltd. | M17: 0.0195
C18: Fund Manager: | G18: Rupesh Patel | I18: Bharat Forge Ltd. | M18: 0.0186
C20: Investment Philosophy | I20: Investment Philosophy
C21: The Nippon India growth fund majorly invest in the mid cap companies in Indian equity market that have potential to consistently perform in future. They identify the potential market leaders, analysing their top line growth and the follow up bottom line growth, in early stage to generate alpha at a pair valuation.Overall their investment strategy is to based on growth at reasonable price.
C33: SIP Performance Chart | I33: 10% Per Annum Step Up SIP Return
C34: SIP Amount of ₹10,000 Per Month | I34: SIP Amount of ₹10,000 per month with 10% increase each year
C48: Fund Overall Oerview
C59: Return Analysis
I61: CAGR %
C62: Particulars | I62: (Last) | J62: 3Yr | K62: 5 | L62: 7 | M62: 10
C63: Nippon Indian Growth Mid Cap Fund | J63: 0.2731 | K63: 0.2382 | L63: 0.2403 | M63: 0.2137
C64: NIFTY Midcap 150 TRI | J64: 0.2326 | K64: 0.209 | L64: 0.2185 | M64: 0.1946
C65: BSE Sensex | J65: 0.2294 | K65: 0.2012 | L65: 0.2105 | M65: 0.1896
C67: Value of ₹1,00,000 invested - Lumpsum
C68: Nippon Indian Growth Mid Cap Fund | J68: =100000*(1+J63) -> 127310 | K68: =100000*(1+K63)^$K$62 -> 291040.88 | L68: =100000*(1+L63)^$K$62 -> 293517.31 | M68: =100000*(1+M63)^$K$62 -> 263364.21
C69: NIFTY Midcap 150 TRI | J69: 187269 | K69: 258304 | L69: 398822 | M69: 591868
C70: BSE Sensex | J70: 185815 | K70: 250079 | L70: 380850 | M70: 567557
C72: Value of ₹10,000 invested - Monthly SIP
C73: Nippon Indian Growth Mid Cap Fund | I73: {=TRANSPOSE(Sheet2!E33:E37)} -> 125636 | J73: 265538 | K73: 479056 | L73: 731297 | M73: 1033168
C74: NIFTY Midcap 150 TRI | I74: {=TRANSPOSE(Sheet2!G33:G37)} -> 126921 | J74: 263191 | K74: 467027 | L74: 704945 | M74: 981590
C75: BSE Sensex | I75: {=TRANSPOSE(Sheet2!I33:I37)} -> 127051 | J75: 262574 | K75: 427889 | L75: 611071 | M75: 812532
C77: Value of ₹10,000 invested - 10% Step Up SIP
C78: Nippon Indian Growth Mid Cap Fund | I78: {=TRANSPOSE(Sheet2!E40:E44)} -> 125636 | J78: 278102 | K78: 519430 | L78: 1207847 | M78: 2484871
C79: NIFTY Midcap 150 TRI | I79: {=TRANSPOSE(Sheet2!G40:G44)} -> 116039 | J79: 253329 | K79: 475820 | L79: 773305 | M79: 1164420
C80: BSE Sensex | I80: {=TRANSPOSE(Sheet2!I40:I44)} -> 125264 | J80: 269715 | K80: 456293 | L80: 682434 | M80: 942815
C88: Risk Analysis
G89: Mean Return | I89: Std Dev | J89: Shape | K89: Sortino | L89: Beta | M89: Alpha
C90: Nippon India Growth Mid Cap Dir | G90: 24.35 | I90: 15.42 | J90: 1.18 | K90: 1.74 | L90: 0.95 | M90: 3.48
...

Sheet Data>

Sheet Portfolio
B1: Company | C1: Sector | D1: Assets %
B2: BSE Ltd. | C2: Financials | D2: 3.52
B3: Fortis Healthcare Ltd. | C3: Healthcare | D3: 2.96
B4: The Federal Bank Ltd. | C4: Financials | D4: 2.52 | F4: Row Labels | G4: Sum of Assets %
B5: AU Small Finance Bank Ltd. | C5: Financials | D5: 2.5 | F5: Automobile and Ancillaries | G5: 13.45
B6: Persistent Systems Ltd. | C6: Technology | D6: 2.48 | F6: Capital Goods | G6: 5.93
B7: Cholamandalam Financial Holdings Ltd. | C7: Financials | D7: 2.34 | F7: Chemicals | G7: 1.74
B8: Voltas Ltd. | C8: Consumer Durables | D8: 2.26 | F8: Construction | G8: 2.76
B9: Max Financial Services Ltd. | C9: Financials | D9: 2.06 | F9: Consumer Durables | G9: 7.11
B10: Ashok Leyland Ltd. | C10: Automobile and Ancillaries | D10: 1.95 | F10: Diversified | G10: 0.5
B11: Bharat Forge Ltd. | C11: Automobile and Ancillaries | D11: 1.86 | F11: Energy | G11: 6.84
B12: Max Healthcare Institute Ltd. | C12: Healthcare | D12: 1.74 | F12: Financials | G12: 27.03
B13: One97 Communications Ltd. | C13: Financials | D13: 1.73 | F13: FMCG | G13: 5.39
B14: Indus Towers Ltd. | C14: Media and Communications | D14: 1.72 | F14: Healthcare | G14: 11.4
B15: Power Finance Corporation Ltd. | C15: Financials | D15: 1.66 | F15: Logistics | G15: 0.64
B16: Indian Bank | C16: Financials | D16: 1.66 | F16: Media and Communications | G16: 1.97
... B22: Samvardhana Motherson International Ltd. | C22: Automobile and Ancillaries | D22: 1.41 | F22: Grand Total | G22: 98.13
B23: Cummins India Ltd. | C23: Automobile and Ancillaries | D23: 1.39
B24: Eternal Ltd. | C24: Retail and Other Services | D24: 1.36
B25: NTPC Green Energy Ltd. | C25: Energy | D25: 1.35
B26: Info Edge (India) Ltd. | C26: Technology | D26: 1.33
B27: GE Vernova T&D India Ltd. | C27: Capital Goods | D27: 1.31
B28: HDB Financial Services Ltd. | C28: Financials | D28: 1.29
B29: Lupin Ltd. | C29: Healthcare | D29: 1.26
B30: Bharat Heavy Electricals Ltd. | C30: Capital Goods | D30: 1.26
B31: APL Apollo Tubes Ltd. | C31: Metals | D31: 1.23
B32: ICICI Lombard General Insurance Company Ltd. | C32: Financials | D32: 1.22
B33: Gland Pharma Ltd. | C33: Healthcare | D33: 1.17
B34: Vishal Mega Mart Ltd. | C34: Retail and Other Services | D34: 1.13
... B98: Globsyn Technologies Limited | C98: Retail and Other Services | D98: 0

Sheet sector 
B2: Sector | C2: Allocation %
B3: Financials | C3: 0.2703
B4: Automobile and Ancillaries | C4: 0.1345
B5: Healthcare | C5: 0.114
B6: Consumer Durables | C6: 0.0711
B7: Energy | C7: 0.0684
B8: Capital Goods | C8: 0.0593
B9: FMCG | C9: 0.0539 | F9: 100
B10: Retail and Other Services | C10: 0.0481
B11: Technology | C11: 0.0455
B12: Construction | C12: 0.0276
B13: Media and Communications | C13: 0.0197
B14: Travel | C14: 0.019
B15: Chemicals | C15: 0.0174
B16: Metals | C16: 0.0123
B17: Textile | C17: 0.0088
B18: Logistics | C18: 0.0064
B19: Diversified | C19: 0.005

Sheet Sheet2
B2: SIP Return @ ₹10,000/Month
B3: Tenur (Years) | C3: Invested Value | D3: Market Value | E3: XIRR
B4: 1 | C4: 120000 | D4: 125636 | E4: 0.0831
B5: 2 | C5: 240000 | D5: 265538 | E5: 0.1006
B6: 3 | C6: 360000 | D6: 479056 | E6: 0.1947
B7: 5 | C7: 600000 | D7: 1033168 | E7: 0.219
B8: 7 | C8: 840000 | D8: 2007828 | E8: 0.2449
B9: 10 | C9: 1200000 | D9: 3692981 | E9: 0.213
B11: 10% Per Annum Step Up SIP Return
B12: Tenur (Years) | C12: Invested Value | D12: Market Value | E12: XIRR
B13: 1 | C13: 120000 | D13: 125636 | E13: 0.0831
B14: 2 | C14: 2,52,000 | D14: 278102 | E14: 0.1003
B15: 3 | C15: 397200 | D15: 519430 | E15: 0.1901
B16: 5 | C16: 732612 | D16: 1207847 | E16: 0.2163
B17: 7 | C17: 1138461 | D17: 2484871 | E17: 0.2421
B18: 10 | C18: 1912921 | D18: 5146326 | E18: 0.2158
C32: Tenur (Years) | D32: Invested Value | E32: Market Value | F32: MF | G32: MidCap ETF | H32: MidCap ETF | I32: Sensex ETF | J32: Sensex ETF | O32: Fund | P32: Category | Q32: Index
C33: 1 | D33: 120000 | E33: 125636 | F33: 0.0831 | G33: 126921 | H33: 0.1087 | I33: 127051 | J33: 0.1108 | N33: Price/Earnings | O33: 24.26 | P33: 27.33 | Q33: 20.37
C34: 2 | D34: 240000 | E34: 265538 | F34: 0.1006 | G34: 263191 | H34: 0.0915 | I34: 262574 | J34: 0.0891 | N34: Price/Book | O34: 3.42 | P34: 4 | Q34: 2.94
C35: 3 | D35: 360000 | E35: 479056 | F35: 0.1947 | G35: 467027 | H35: 0.1766 | I35: 427889 | J35: 0.1155 | N35: Price/Sales | O35: 2.77 | P35: 3.08 | Q35: 2.64
C36: 4 | D36: 480000 | E36: 731297 | F36: 0.2143 | G36: 704945 | H36: 0.195 | I36: 611071 | J36: 0.1209 | N36: Price/Cash Flow | O36: 21.88 | P36: 23.23 | Q36: 16.16
C37: 5 | D37: 600000 | E37: 1033168 | F37: 0.219 | G37: 981590 | H37: 0.1979 | I37: 812532 | J37: 0.1208 | N37: Dividend Yield % | O37: 0.96 | P37: 0.85 | Q37: 1.37
N38: Long-Term Earnings % | O38: 13.09 | P38: 14.92 | Q38: 12.62
C39: Tenur (Years) | D39: Invested Value | E39: Market Value | F39: MF | G39: MidCap ETF | H39: MidCap ETF | I39: Sensex ETF | J39: Sensex ETF | N39: Book Value Growth | O39: 15.73 | P39: 14.73 | Q39: 16.04
C40: 1 | D40: =D33 -> 120000 | E40: =D13 -> 125636 | F40: =E13 -> 0.0831 | G40: 116039 | H40: -0.0603 | I40: 125264 | J40: 0.0819
C41: 2 | D41: 240000 | E41: =D14 -> 278102 | F41: =E14 -> 0.1003 | G41: 253329 | H41: 0.0013 | I41: 269715 | J41: 0.0682
C42: 3 | D42: 360000 | E42: =D15 -> 519430 | F42: =E15 -> 0.1901 | G42: 475820 | H42: 0.1259 | I42: 456293 | J42: 0.096
C43: 4 | D43: 480000 | E43: =D16 -> 1207847 | F43: =E16 -> 0.2163 | G43: 773305 | H43: 0.1754 | I43: 682434 | J43: 0.1074
C44: 5 | D44: 600000 | E44: =D17 -> 2484871 | F44: =E17 -> 0.2421 | G44: 1164420 | H44: 0.2 | I44: 942815 | J44: 0.108 | N44: Category
N45: Cyclical
N46: Cyclical
N47: Cyclical
N48: Cyclical
N49: Sensitive
N50: Sensitive
N51: Sensitive
N52: Sensitive
N53: Defensive
N54: Defensive
N55: Defensive
...

Sheet Nippon_India_Growth_Mid_Cap_Fun
I1: h9
A2: Equity Holdings
A3: BSE Limited | B3: 3.42 | C3: 5100000 | D3: 3.19 | E3: 5100000 | F3: 3.52 | G3: 5100000 | H3: =E3-G3 -> 0 | I3: =E3/G3-1 -> 0
A4: The Federal Bank Limited | B4: 2.83 | C4: 41000000 | D4: 2.6 | E4: 41000000 | F4: 2.52 | G4: 41000000 | H4: =E4-G4 -> 0 | I4: =E4/G4-1 -> 0
A5: Fortis Healthcare Limited | B5: 2.76 | C5: 13542021 | D5: 2.84 | E5: 13542021 | F5: 2.96 | G5: 13542021 | H5: =E5-G5 -> 0 | I5: =E5/G5-1 -> 0
A6: AU Small Finance Bank Limited | B6: 2.59 | C6: 11000000 | D6: 2.6 | E6: 11000000 | F6: 2.5 | G6: 11000000 | H6: =E6-G6 -> 0 | I6: =E6/G6-1 -> 0
A7: Persistent Systems Limited | B7: 2.38 | C7: 1644232 | D7: 2.45 | E7: 1644232 | F7: 2.48 | G7: 1644232 | H7: =E7-G7 -> 0 | I7: =E7/G7-1 -> 0
A8: Voltas Limited | B8: 2.2 | C8: 6909978 | D8: 2.23 | E8: 6909978 | F8: 2.26 | G8: 6909978 | H8: =E8-G8 -> 0 | I8: =E8/G8-1 -> 0
A9: Ashok Leyland Limited | B9: 2.12 | C9: 45000000 | D9: 2.21 | E9: 51844304 | F9: 1.95 | G9: 51844304 | H9: =E9-G9 -> 0 | I9: =E9/G9-1 -> 0
A10: Cholamandalam Financial Holdings Limited | B10: 2.12 | C10: 5335000 | D10: 2.3 | E10: 5335000 | F10: 2.34 | G10: 5335000 | H10: =E10-G10 -> 0 | I10: =E10/G10-1 -> 0
A11: Max Financial Services Limited | B11: 1.97 | C11: 5100000 | D11: 2.02 | E11: 5100000 | F11: 2.06 | G11: 5100000 | H11: =E11-G11 -> 0 | I11: =E11/G11-1 -> 0
A12: Indus Towers Limited | B12: 1.92 | C12: 18000000 | D12: 1.79 | E12: 18000000 | F12: 1.72 | G12: 18000000 | H12: =E12-G12 -> 0 | I12: =E12/G12-1 -> 0
A13: Bharat Forge Limited | B13: 1.88 | C13: 5444007 | D13: 1.9 | E13: 5444007 | F13: 1.86 | G13: 5444007 | H13: =E13-G13 -> 0 | I13: =E13/G13-1 -> 0
A14: Indian Bank | B14: 1.75 | C14: 8000000 | D14: 1.59 | E14: 8000000 | F14: 1.66 | G14: 8000000 | H14: =E14-G14 -> 0 | I14: =E14/G14-1 -> 0
... A97: Colgate Palmolive (India) Limited | B97: 0.66 | C97: 1300000 | D97: 0.64 | E97: 1300000 | F97: 0.57 | G97: 1100000 | H97: =E97-G97 -> 200000 | I97: =E97/G97-1 -> 0.18181818
A98: ICICI Bank Limited | B98: 0.88 | C98: 2703508 | D98: - | E98: - | F98: - | G98: - | H98: =E98-G98 -> #VALUE! | I98: =E98/G98-1 -> #VALUE!
A99: ITC Hotels Limited | B99: 0.61 | C99: 14000000 | D99: 0.66 | E99: 14000000 | F99: - | G99: - | H99: =E99-G99 -> #VALUE! | I99: =E99/G99-1 -> #VALUE!
A100: Swiggy Limited | B100: 0.52 | C100: 7000000 | D100: - | E100: - | F100: 0.32 | G100: 3588516 | H100: =E100-G100 -> #VALUE! | I100: =E100/G100-1 -> #VALUE!
A101: ICICI Prudential Asset Management Company Limited | B101: 0.08 | C101: 117766 | D101: 0.07 | E101: 117766 | F101: - | G101: - | H101: =E101-G101 -> #VALUE! | I101: =E101/G101-1 -> #VALUE!
A102: Sona BLW Precision Forgings Limited | B102: - | C102: - | D102: - | E102: - | F102: 0.36 | G102: 2987915 | H102: =E102-G102 -> #VALUE! | I102: =E102/G102-1 -> #VALUE!
A103: Company | B103: Jan-26 AUM:â‚¹41727.4(Cr.) | D103: Dec-25 AUM:â‚¹42124.5(Cr.) | F103: Nov-25 AUM:â‚¹42041.6(Cr.)
B104: % of AUM | C104: No. of Shares | D104: % of AUM | E104: No. of Shares | F104: % of AUM | G104: No. of Shares | H104: Addation/Deletion
